INFO:tornado.access:200 POST /login (127.0.0.1) 1.06ms
INFO:tornado.general:/home/zzg/PycharmProjects/MyTornado/server.py modified; restarting server
INFO:tornado.general:/home/zzg/PycharmProjects/MyTornado/server.py modified; restarting server
INFO:tornado.general:/home/zzg/PycharmProjects/MyTornado/server.py modified; restarting server
INFO:tornado.general:/home/zzg/PycharmProjects/MyTornado/server.py modified; restarting server
INFO:tornado.general:/home/zzg/PycharmProjects/MyTornado/server.py modified; restarting server
INFO:tornado.access:200 POST /login (127.0.0.1) 0.99ms
INFO:tornado.access:200 POST /login (127.0.0.1) 0.61ms
INFO:tornado.access:200 POST /login (127.0.0.1) 0.62ms
INFO:tornado.access:200 POST /login (127.0.0.1) 0.61ms
INFO:tornado.access:200 POST /login (127.0.0.1) 0.65ms
WARNING:tornado.access:404 GET / (::1) 2.97ms
WARNING:tornado.access:404 GET /favicon.ico (::1) 4.00ms
INFO:tornado.access:200 GET /login (::1) 1.00ms
WARNING:tornado.access:404 GET / (::1) 3.00ms
WARNING:tornado.access:404 GET / (::1) 0.00ms
WARNING:tornado.access:404 GET /login/ (::1) 1.02ms
WARNING:tornado.access:404 GET /login/ (::1) 1.00ms
INFO:tornado.general:C:\Users\Ð¡Æß\Desktop\MyTornado\settings\config.py modified; restarting server
WARNING:tornado.access:404 GET / (::1) 2.01ms
WARNING:tornado.access:404 GET /favicon.ico (::1) 4.08ms
INFO:tornado.access:200 GET /login (::1) 1.00ms
INFO:tornado.access:304 GET /login (::1) 0.00ms
INFO:tornado.access:200 GET /fuzz-loadscriptlist (127.0.0.1) 2.03ms
INFO:tornado.access:200 GET /login (::1) 122.96ms
INFO:tornado.access:304 GET /login (::1) 35.04ms
INFO:tornado.access:200 GET /login?username=liubin&password=123456 (127.0.0.1) 75.64ms
INFO:tornado.access:200 GET /login (::1) 125.90ms
INFO:tornado.access:304 GET /login (::1) 34.54ms
INFO:tornado.access:304 GET /login (::1) 58.37ms
INFO:tornado.access:304 GET /login (::1) 46.09ms
INFO:tornado.access:304 GET /login (::1) 49.55ms
INFO:tornado.access:304 GET /login (::1) 35.31ms
INFO:tornado.access:304 GET /login (::1) 38.14ms
INFO:tornado.access:304 GET /login (::1) 35.43ms
INFO:tornado.access:304 GET /login (::1) 36.00ms
INFO:tornado.access:304 GET /login (::1) 34.78ms
INFO:tornado.access:304 GET /login (::1) 35.39ms
INFO:tornado.access:304 GET /login (::1) 54.46ms
INFO:tornado.access:304 GET /login (::1) 41.47ms
INFO:tornado.access:304 GET /login (::1) 34.92ms
INFO:tornado.access:304 GET /login (::1) 34.58ms
INFO:tornado.access:304 GET /login (::1) 35.53ms
INFO:tornado.access:304 GET /login (::1) 57.16ms
INFO:tornado.access:304 GET /login (::1) 32.86ms
INFO:tornado.access:304 GET /login (::1) 34.08ms
INFO:tornado.access:304 GET /login (::1) 48.55ms
INFO:tornado.access:304 GET /login (::1) 33.84ms
INFO:tornado.access:304 GET /login (::1) 33.60ms
INFO:tornado.access:304 GET /login (::1) 36.64ms
INFO:tornado.access:304 GET /login (::1) 33.96ms
INFO:tornado.access:304 GET /login (::1) 55.00ms
INFO:tornado.access:304 GET /login (::1) 53.22ms
INFO:tornado.access:304 GET /login (::1) 36.00ms
INFO:tornado.access:304 GET /login (::1) 35.02ms
INFO:tornado.access:304 GET /login (::1) 53.09ms
INFO:tornado.access:304 GET /login (::1) 36.56ms
INFO:tornado.access:304 GET /login (::1) 53.82ms
INFO:tornado.access:304 GET /login (::1) 35.01ms
INFO:tornado.access:304 GET /login (::1) 35.84ms
INFO:tornado.access:304 GET /login (::1) 53.00ms
INFO:tornado.access:304 GET /login (::1) 55.00ms
INFO:tornado.access:304 GET /login (::1) 35.64ms
INFO:tornado.access:304 GET /login (::1) 37.00ms
WARNING:tornado.access:404 GET / (192.168.2.89) 3.00ms
WARNING:tornado.access:404 GET /favicon.ico (192.168.2.89) 2.00ms
ERROR:tornado.application:Uncaught exception GET /login (192.168.2.89)
HTTPServerRequest(protocol='http', host='192.168.2.89:8080', method='GET', uri='/login', version='HTTP/1.1', remote_ip='192.168.2.89')
Traceback (most recent call last):
  File "D:\ProgramData\Anaconda3\envs\py36\lib\site-packages\pymysql\connections.py", line 614, in connect
    (self.host, self.port), self.connect_timeout, **kwargs
  File "D:\ProgramData\Anaconda3\envs\py36\lib\socket.py", line 724, in create_connection
    raise err
  File "D:\ProgramData\Anaconda3\envs\py36\lib\socket.py", line 713, in create_connection
    sock.connect(sa)
socket.timeout: timed out

During handling of the above exception, another exception occurred:

Traceback (most recent call last):
  File "D:\ProgramData\Anaconda3\envs\py36\lib\site-packages\sqlalchemy\engine\base.py", line 2336, in _wrap_pool_connect
    return fn()
  File "D:\ProgramData\Anaconda3\envs\py36\lib\site-packages\sqlalchemy\pool\base.py", line 364, in connect
    return _ConnectionFairy._checkout(self)
  File "D:\ProgramData\Anaconda3\envs\py36\lib\site-packages\sqlalchemy\pool\base.py", line 778, in _checkout
    fairy = _ConnectionRecord.checkout(pool)
  File "D:\ProgramData\Anaconda3\envs\py36\lib\site-packages\sqlalchemy\pool\base.py", line 495, in checkout
    rec = pool._do_get()
  File "D:\ProgramData\Anaconda3\envs\py36\lib\site-packages\sqlalchemy\pool\impl.py", line 140, in _do_get
    self._dec_overflow()
  File "D:\ProgramData\Anaconda3\envs\py36\lib\site-packages\sqlalchemy\util\langhelpers.py", line 70, in __exit__
    with_traceback=exc_tb,
  File "D:\ProgramData\Anaconda3\envs\py36\lib\site-packages\sqlalchemy\util\compat.py", line 182, in raise_
    raise exception
  File "D:\ProgramData\Anaconda3\envs\py36\lib\site-packages\sqlalchemy\pool\impl.py", line 137, in _do_get
    return self._create_connection()
  File "D:\ProgramData\Anaconda3\envs\py36\lib\site-packages\sqlalchemy\pool\base.py", line 309, in _create_connection
    return _ConnectionRecord(self)
  File "D:\ProgramData\Anaconda3\envs\py36\lib\site-packages\sqlalchemy\pool\base.py", line 440, in __init__
    self.__connect(first_connect_check=True)
  File "D:\ProgramData\Anaconda3\envs\py36\lib\site-packages\sqlalchemy\pool\base.py", line 661, in __connect
    pool.logger.debug("Error on connect(): %s", e)
  File "D:\ProgramData\Anaconda3\envs\py36\lib\site-packages\sqlalchemy\util\langhelpers.py", line 70, in __exit__
    with_traceback=exc_tb,
  File "D:\ProgramData\Anaconda3\envs\py36\lib\site-packages\sqlalchemy\util\compat.py", line 182, in raise_
    raise exception
  File "D:\ProgramData\Anaconda3\envs\py36\lib\site-packages\sqlalchemy\pool\base.py", line 656, in __connect
    connection = pool._invoke_creator(self)
  File "D:\ProgramData\Anaconda3\envs\py36\lib\site-packages\sqlalchemy\engine\strategies.py", line 114, in connect
    return dialect.connect(*cargs, **cparams)
  File "D:\ProgramData\Anaconda3\envs\py36\lib\site-packages\sqlalchemy\engine\default.py", line 508, in connect
    return self.dbapi.connect(*cargs, **cparams)
  File "D:\ProgramData\Anaconda3\envs\py36\lib\site-packages\pymysql\connections.py", line 353, in __init__
    self.connect()
  File "D:\ProgramData\Anaconda3\envs\py36\lib\site-packages\pymysql\connections.py", line 664, in connect
    raise exc
pymysql.err.OperationalError: (2003, "Can't connect to MySQL server on '192.168.8.58' (timed out)")

The above exception was the direct cause of the following exception:

Traceback (most recent call last):
  File "D:\ProgramData\Anaconda3\envs\py36\lib\site-packages\tornado\web.py", line 1590, in _execute
    result = method(*self.path_args, **self.path_kwargs)
  File "C:\Users\Ð¡Æß\Desktop\MyTornado\handlers\public\loginhandle.py", line 21, in get
    user.open()
  File "C:\Users\Ð¡Æß\Desktop\MyTornado\handlers\public\sql_orm.py", line 38, in open
    Base.metadata.create_all(engine)
  File "D:\ProgramData\Anaconda3\envs\py36\lib\site-packages\sqlalchemy\sql\schema.py", line 4664, in create_all
    ddl.SchemaGenerator, self, checkfirst=checkfirst, tables=tables
  File "D:\ProgramData\Anaconda3\envs\py36\lib\site-packages\sqlalchemy\engine\base.py", line 2094, in _run_visitor
    with self._optional_conn_ctx_manager(connection) as conn:
  File "D:\ProgramData\Anaconda3\envs\py36\lib\contextlib.py", line 81, in __enter__
    return next(self.gen)
  File "D:\ProgramData\Anaconda3\envs\py36\lib\site-packages\sqlalchemy\engine\base.py", line 2086, in _optional_conn_ctx_manager
    with self._contextual_connect() as conn:
  File "D:\ProgramData\Anaconda3\envs\py36\lib\site-packages\sqlalchemy\engine\base.py", line 2302, in _contextual_connect
    self._wrap_pool_connect(self.pool.connect, None),
  File "D:\ProgramData\Anaconda3\envs\py36\lib\site-packages\sqlalchemy\engine\base.py", line 2340, in _wrap_pool_connect
    e, dialect, self
  File "D:\ProgramData\Anaconda3\envs\py36\lib\site-packages\sqlalchemy\engine\base.py", line 1584, in _handle_dbapi_exception_noconnection
    sqlalchemy_exception, with_traceback=exc_info[2], from_=e
  File "D:\ProgramData\Anaconda3\envs\py36\lib\site-packages\sqlalchemy\util\compat.py", line 182, in raise_
    raise exception
  File "D:\ProgramData\Anaconda3\envs\py36\lib\site-packages\sqlalchemy\engine\base.py", line 2336, in _wrap_pool_connect
    return fn()
  File "D:\ProgramData\Anaconda3\envs\py36\lib\site-packages\sqlalchemy\pool\base.py", line 364, in connect
    return _ConnectionFairy._checkout(self)
  File "D:\ProgramData\Anaconda3\envs\py36\lib\site-packages\sqlalchemy\pool\base.py", line 778, in _checkout
    fairy = _ConnectionRecord.checkout(pool)
  File "D:\ProgramData\Anaconda3\envs\py36\lib\site-packages\sqlalchemy\pool\base.py", line 495, in checkout
    rec = pool._do_get()
  File "D:\ProgramData\Anaconda3\envs\py36\lib\site-packages\sqlalchemy\pool\impl.py", line 140, in _do_get
    self._dec_overflow()
  File "D:\ProgramData\Anaconda3\envs\py36\lib\site-packages\sqlalchemy\util\langhelpers.py", line 70, in __exit__
    with_traceback=exc_tb,
  File "D:\ProgramData\Anaconda3\envs\py36\lib\site-packages\sqlalchemy\util\compat.py", line 182, in raise_
    raise exception
  File "D:\ProgramData\Anaconda3\envs\py36\lib\site-packages\sqlalchemy\pool\impl.py", line 137, in _do_get
    return self._create_connection()
  File "D:\ProgramData\Anaconda3\envs\py36\lib\site-packages\sqlalchemy\pool\base.py", line 309, in _create_connection
    return _ConnectionRecord(self)
  File "D:\ProgramData\Anaconda3\envs\py36\lib\site-packages\sqlalchemy\pool\base.py", line 440, in __init__
    self.__connect(first_connect_check=True)
  File "D:\ProgramData\Anaconda3\envs\py36\lib\site-packages\sqlalchemy\pool\base.py", line 661, in __connect
    pool.logger.debug("Error on connect(): %s", e)
  File "D:\ProgramData\Anaconda3\envs\py36\lib\site-packages\sqlalchemy\util\langhelpers.py", line 70, in __exit__
    with_traceback=exc_tb,
  File "D:\ProgramData\Anaconda3\envs\py36\lib\site-packages\sqlalchemy\util\compat.py", line 182, in raise_
    raise exception
  File "D:\ProgramData\Anaconda3\envs\py36\lib\site-packages\sqlalchemy\pool\base.py", line 656, in __connect
    connection = pool._invoke_creator(self)
  File "D:\ProgramData\Anaconda3\envs\py36\lib\site-packages\sqlalchemy\engine\strategies.py", line 114, in connect
    return dialect.connect(*cargs, **cparams)
  File "D:\ProgramData\Anaconda3\envs\py36\lib\site-packages\sqlalchemy\engine\default.py", line 508, in connect
    return self.dbapi.connect(*cargs, **cparams)
  File "D:\ProgramData\Anaconda3\envs\py36\lib\site-packages\pymysql\connections.py", line 353, in __init__
    self.connect()
  File "D:\ProgramData\Anaconda3\envs\py36\lib\site-packages\pymysql\connections.py", line 664, in connect
    raise exc
sqlalchemy.exc.OperationalError: (pymysql.err.OperationalError) (2003, "Can't connect to MySQL server on '192.168.8.58' (timed out)")
(Background on this error at: http://sqlalche.me/e/13/e3q8)
ERROR:tornado.access:500 GET /login (192.168.2.89) 10122.35ms
ERROR:tornado.application:Uncaught exception GET /login (192.168.2.89)
HTTPServerRequest(protocol='http', host='192.168.2.89:8080', method='GET', uri='/login', version='HTTP/1.1', remote_ip='192.168.2.89')
Traceback (most recent call last):
  File "D:\ProgramData\Anaconda3\envs\py36\lib\site-packages\pymysql\connections.py", line 614, in connect
    (self.host, self.port), self.connect_timeout, **kwargs
  File "D:\ProgramData\Anaconda3\envs\py36\lib\socket.py", line 724, in create_connection
    raise err
  File "D:\ProgramData\Anaconda3\envs\py36\lib\socket.py", line 713, in create_connection
    sock.connect(sa)
socket.timeout: timed out

During handling of the above exception, another exception occurred:

Traceback (most recent call last):
  File "D:\ProgramData\Anaconda3\envs\py36\lib\site-packages\sqlalchemy\engine\base.py", line 2336, in _wrap_pool_connect
    return fn()
  File "D:\ProgramData\Anaconda3\envs\py36\lib\site-packages\sqlalchemy\pool\base.py", line 364, in connect
    return _ConnectionFairy._checkout(self)
  File "D:\ProgramData\Anaconda3\envs\py36\lib\site-packages\sqlalchemy\pool\base.py", line 778, in _checkout
    fairy = _ConnectionRecord.checkout(pool)
  File "D:\ProgramData\Anaconda3\envs\py36\lib\site-packages\sqlalchemy\pool\base.py", line 495, in checkout
    rec = pool._do_get()
  File "D:\ProgramData\Anaconda3\envs\py36\lib\site-packages\sqlalchemy\pool\impl.py", line 140, in _do_get
    self._dec_overflow()
  File "D:\ProgramData\Anaconda3\envs\py36\lib\site-packages\sqlalchemy\util\langhelpers.py", line 70, in __exit__
    with_traceback=exc_tb,
  File "D:\ProgramData\Anaconda3\envs\py36\lib\site-packages\sqlalchemy\util\compat.py", line 182, in raise_
    raise exception
  File "D:\ProgramData\Anaconda3\envs\py36\lib\site-packages\sqlalchemy\pool\impl.py", line 137, in _do_get
    return self._create_connection()
  File "D:\ProgramData\Anaconda3\envs\py36\lib\site-packages\sqlalchemy\pool\base.py", line 309, in _create_connection
    return _ConnectionRecord(self)
  File "D:\ProgramData\Anaconda3\envs\py36\lib\site-packages\sqlalchemy\pool\base.py", line 440, in __init__
    self.__connect(first_connect_check=True)
  File "D:\ProgramData\Anaconda3\envs\py36\lib\site-packages\sqlalchemy\pool\base.py", line 661, in __connect
    pool.logger.debug("Error on connect(): %s", e)
  File "D:\ProgramData\Anaconda3\envs\py36\lib\site-packages\sqlalchemy\util\langhelpers.py", line 70, in __exit__
    with_traceback=exc_tb,
  File "D:\ProgramData\Anaconda3\envs\py36\lib\site-packages\sqlalchemy\util\compat.py", line 182, in raise_
    raise exception
  File "D:\ProgramData\Anaconda3\envs\py36\lib\site-packages\sqlalchemy\pool\base.py", line 656, in __connect
    connection = pool._invoke_creator(self)
  File "D:\ProgramData\Anaconda3\envs\py36\lib\site-packages\sqlalchemy\engine\strategies.py", line 114, in connect
    return dialect.connect(*cargs, **cparams)
  File "D:\ProgramData\Anaconda3\envs\py36\lib\site-packages\sqlalchemy\engine\default.py", line 508, in connect
    return self.dbapi.connect(*cargs, **cparams)
  File "D:\ProgramData\Anaconda3\envs\py36\lib\site-packages\pymysql\connections.py", line 353, in __init__
    self.connect()
  File "D:\ProgramData\Anaconda3\envs\py36\lib\site-packages\pymysql\connections.py", line 664, in connect
    raise exc
pymysql.err.OperationalError: (2003, "Can't connect to MySQL server on '192.168.8.58' (timed out)")

The above exception was the direct cause of the following exception:

Traceback (most recent call last):
  File "D:\ProgramData\Anaconda3\envs\py36\lib\site-packages\tornado\web.py", line 1590, in _execute
    result = method(*self.path_args, **self.path_kwargs)
  File "C:\Users\Ð¡Æß\Desktop\MyTornado\handlers\public\loginhandle.py", line 21, in get
    user.open()
  File "C:\Users\Ð¡Æß\Desktop\MyTornado\handlers\public\sql_orm.py", line 38, in open
    Base.metadata.create_all(engine)
  File "D:\ProgramData\Anaconda3\envs\py36\lib\site-packages\sqlalchemy\sql\schema.py", line 4664, in create_all
    ddl.SchemaGenerator, self, checkfirst=checkfirst, tables=tables
  File "D:\ProgramData\Anaconda3\envs\py36\lib\site-packages\sqlalchemy\engine\base.py", line 2094, in _run_visitor
    with self._optional_conn_ctx_manager(connection) as conn:
  File "D:\ProgramData\Anaconda3\envs\py36\lib\contextlib.py", line 81, in __enter__
    return next(self.gen)
  File "D:\ProgramData\Anaconda3\envs\py36\lib\site-packages\sqlalchemy\engine\base.py", line 2086, in _optional_conn_ctx_manager
    with self._contextual_connect() as conn:
  File "D:\ProgramData\Anaconda3\envs\py36\lib\site-packages\sqlalchemy\engine\base.py", line 2302, in _contextual_connect
    self._wrap_pool_connect(self.pool.connect, None),
  File "D:\ProgramData\Anaconda3\envs\py36\lib\site-packages\sqlalchemy\engine\base.py", line 2340, in _wrap_pool_connect
    e, dialect, self
  File "D:\ProgramData\Anaconda3\envs\py36\lib\site-packages\sqlalchemy\engine\base.py", line 1584, in _handle_dbapi_exception_noconnection
    sqlalchemy_exception, with_traceback=exc_info[2], from_=e
  File "D:\ProgramData\Anaconda3\envs\py36\lib\site-packages\sqlalchemy\util\compat.py", line 182, in raise_
    raise exception
  File "D:\ProgramData\Anaconda3\envs\py36\lib\site-packages\sqlalchemy\engine\base.py", line 2336, in _wrap_pool_connect
    return fn()
  File "D:\ProgramData\Anaconda3\envs\py36\lib\site-packages\sqlalchemy\pool\base.py", line 364, in connect
    return _ConnectionFairy._checkout(self)
  File "D:\ProgramData\Anaconda3\envs\py36\lib\site-packages\sqlalchemy\pool\base.py", line 778, in _checkout
    fairy = _ConnectionRecord.checkout(pool)
  File "D:\ProgramData\Anaconda3\envs\py36\lib\site-packages\sqlalchemy\pool\base.py", line 495, in checkout
    rec = pool._do_get()
  File "D:\ProgramData\Anaconda3\envs\py36\lib\site-packages\sqlalchemy\pool\impl.py", line 140, in _do_get
    self._dec_overflow()
  File "D:\ProgramData\Anaconda3\envs\py36\lib\site-packages\sqlalchemy\util\langhelpers.py", line 70, in __exit__
    with_traceback=exc_tb,
  File "D:\ProgramData\Anaconda3\envs\py36\lib\site-packages\sqlalchemy\util\compat.py", line 182, in raise_
    raise exception
  File "D:\ProgramData\Anaconda3\envs\py36\lib\site-packages\sqlalchemy\pool\impl.py", line 137, in _do_get
    return self._create_connection()
  File "D:\ProgramData\Anaconda3\envs\py36\lib\site-packages\sqlalchemy\pool\base.py", line 309, in _create_connection
    return _ConnectionRecord(self)
  File "D:\ProgramData\Anaconda3\envs\py36\lib\site-packages\sqlalchemy\pool\base.py", line 440, in __init__
    self.__connect(first_connect_check=True)
  File "D:\ProgramData\Anaconda3\envs\py36\lib\site-packages\sqlalchemy\pool\base.py", line 661, in __connect
    pool.logger.debug("Error on connect(): %s", e)
  File "D:\ProgramData\Anaconda3\envs\py36\lib\site-packages\sqlalchemy\util\langhelpers.py", line 70, in __exit__
    with_traceback=exc_tb,
  File "D:\ProgramData\Anaconda3\envs\py36\lib\site-packages\sqlalchemy\util\compat.py", line 182, in raise_
    raise exception
  File "D:\ProgramData\Anaconda3\envs\py36\lib\site-packages\sqlalchemy\pool\base.py", line 656, in __connect
    connection = pool._invoke_creator(self)
  File "D:\ProgramData\Anaconda3\envs\py36\lib\site-packages\sqlalchemy\engine\strategies.py", line 114, in connect
    return dialect.connect(*cargs, **cparams)
  File "D:\ProgramData\Anaconda3\envs\py36\lib\site-packages\sqlalchemy\engine\default.py", line 508, in connect
    return self.dbapi.connect(*cargs, **cparams)
  File "D:\ProgramData\Anaconda3\envs\py36\lib\site-packages\pymysql\connections.py", line 353, in __init__
    self.connect()
  File "D:\ProgramData\Anaconda3\envs\py36\lib\site-packages\pymysql\connections.py", line 664, in connect
    raise exc
sqlalchemy.exc.OperationalError: (pymysql.err.OperationalError) (2003, "Can't connect to MySQL server on '192.168.8.58' (timed out)")
(Background on this error at: http://sqlalche.me/e/13/e3q8)
ERROR:tornado.access:500 GET /login (192.168.2.89) 10007.32ms
ERROR:tornado.application:Uncaught exception GET /login (192.168.2.89)
HTTPServerRequest(protocol='http', host='192.168.2.89:8080', method='GET', uri='/login', version='HTTP/1.1', remote_ip='192.168.2.89')
Traceback (most recent call last):
  File "D:\ProgramData\Anaconda3\envs\py36\lib\site-packages\pymysql\connections.py", line 614, in connect
    (self.host, self.port), self.connect_timeout, **kwargs
  File "D:\ProgramData\Anaconda3\envs\py36\lib\socket.py", line 724, in create_connection
    raise err
  File "D:\ProgramData\Anaconda3\envs\py36\lib\socket.py", line 713, in create_connection
    sock.connect(sa)
socket.timeout: timed out

During handling of the above exception, another exception occurred:

Traceback (most recent call last):
  File "D:\ProgramData\Anaconda3\envs\py36\lib\site-packages\sqlalchemy\engine\base.py", line 2336, in _wrap_pool_connect
    return fn()
  File "D:\ProgramData\Anaconda3\envs\py36\lib\site-packages\sqlalchemy\pool\base.py", line 364, in connect
    return _ConnectionFairy._checkout(self)
  File "D:\ProgramData\Anaconda3\envs\py36\lib\site-packages\sqlalchemy\pool\base.py", line 778, in _checkout
    fairy = _ConnectionRecord.checkout(pool)
  File "D:\ProgramData\Anaconda3\envs\py36\lib\site-packages\sqlalchemy\pool\base.py", line 495, in checkout
    rec = pool._do_get()
  File "D:\ProgramData\Anaconda3\envs\py36\lib\site-packages\sqlalchemy\pool\impl.py", line 140, in _do_get
    self._dec_overflow()
  File "D:\ProgramData\Anaconda3\envs\py36\lib\site-packages\sqlalchemy\util\langhelpers.py", line 70, in __exit__
    with_traceback=exc_tb,
  File "D:\ProgramData\Anaconda3\envs\py36\lib\site-packages\sqlalchemy\util\compat.py", line 182, in raise_
    raise exception
  File "D:\ProgramData\Anaconda3\envs\py36\lib\site-packages\sqlalchemy\pool\impl.py", line 137, in _do_get
    return self._create_connection()
  File "D:\ProgramData\Anaconda3\envs\py36\lib\site-packages\sqlalchemy\pool\base.py", line 309, in _create_connection
    return _ConnectionRecord(self)
  File "D:\ProgramData\Anaconda3\envs\py36\lib\site-packages\sqlalchemy\pool\base.py", line 440, in __init__
    self.__connect(first_connect_check=True)
  File "D:\ProgramData\Anaconda3\envs\py36\lib\site-packages\sqlalchemy\pool\base.py", line 661, in __connect
    pool.logger.debug("Error on connect(): %s", e)
  File "D:\ProgramData\Anaconda3\envs\py36\lib\site-packages\sqlalchemy\util\langhelpers.py", line 70, in __exit__
    with_traceback=exc_tb,
  File "D:\ProgramData\Anaconda3\envs\py36\lib\site-packages\sqlalchemy\util\compat.py", line 182, in raise_
    raise exception
  File "D:\ProgramData\Anaconda3\envs\py36\lib\site-packages\sqlalchemy\pool\base.py", line 656, in __connect
    connection = pool._invoke_creator(self)
  File "D:\ProgramData\Anaconda3\envs\py36\lib\site-packages\sqlalchemy\engine\strategies.py", line 114, in connect
    return dialect.connect(*cargs, **cparams)
  File "D:\ProgramData\Anaconda3\envs\py36\lib\site-packages\sqlalchemy\engine\default.py", line 508, in connect
    return self.dbapi.connect(*cargs, **cparams)
  File "D:\ProgramData\Anaconda3\envs\py36\lib\site-packages\pymysql\connections.py", line 353, in __init__
    self.connect()
  File "D:\ProgramData\Anaconda3\envs\py36\lib\site-packages\pymysql\connections.py", line 664, in connect
    raise exc
pymysql.err.OperationalError: (2003, "Can't connect to MySQL server on '192.168.8.58' (timed out)")

The above exception was the direct cause of the following exception:

Traceback (most recent call last):
  File "D:\ProgramData\Anaconda3\envs\py36\lib\site-packages\tornado\web.py", line 1590, in _execute
    result = method(*self.path_args, **self.path_kwargs)
  File "C:\Users\Ð¡Æß\Desktop\MyTornado\handlers\public\loginhandle.py", line 21, in get
    user.open()
  File "C:\Users\Ð¡Æß\Desktop\MyTornado\handlers\public\sql_orm.py", line 38, in open
    Base.metadata.create_all(engine)
  File "D:\ProgramData\Anaconda3\envs\py36\lib\site-packages\sqlalchemy\sql\schema.py", line 4664, in create_all
    ddl.SchemaGenerator, self, checkfirst=checkfirst, tables=tables
  File "D:\ProgramData\Anaconda3\envs\py36\lib\site-packages\sqlalchemy\engine\base.py", line 2094, in _run_visitor
    with self._optional_conn_ctx_manager(connection) as conn:
  File "D:\ProgramData\Anaconda3\envs\py36\lib\contextlib.py", line 81, in __enter__
    return next(self.gen)
  File "D:\ProgramData\Anaconda3\envs\py36\lib\site-packages\sqlalchemy\engine\base.py", line 2086, in _optional_conn_ctx_manager
    with self._contextual_connect() as conn:
  File "D:\ProgramData\Anaconda3\envs\py36\lib\site-packages\sqlalchemy\engine\base.py", line 2302, in _contextual_connect
    self._wrap_pool_connect(self.pool.connect, None),
  File "D:\ProgramData\Anaconda3\envs\py36\lib\site-packages\sqlalchemy\engine\base.py", line 2340, in _wrap_pool_connect
    e, dialect, self
  File "D:\ProgramData\Anaconda3\envs\py36\lib\site-packages\sqlalchemy\engine\base.py", line 1584, in _handle_dbapi_exception_noconnection
    sqlalchemy_exception, with_traceback=exc_info[2], from_=e
  File "D:\ProgramData\Anaconda3\envs\py36\lib\site-packages\sqlalchemy\util\compat.py", line 182, in raise_
    raise exception
  File "D:\ProgramData\Anaconda3\envs\py36\lib\site-packages\sqlalchemy\engine\base.py", line 2336, in _wrap_pool_connect
    return fn()
  File "D:\ProgramData\Anaconda3\envs\py36\lib\site-packages\sqlalchemy\pool\base.py", line 364, in connect
    return _ConnectionFairy._checkout(self)
  File "D:\ProgramData\Anaconda3\envs\py36\lib\site-packages\sqlalchemy\pool\base.py", line 778, in _checkout
    fairy = _ConnectionRecord.checkout(pool)
  File "D:\ProgramData\Anaconda3\envs\py36\lib\site-packages\sqlalchemy\pool\base.py", line 495, in checkout
    rec = pool._do_get()
  File "D:\ProgramData\Anaconda3\envs\py36\lib\site-packages\sqlalchemy\pool\impl.py", line 140, in _do_get
    self._dec_overflow()
  File "D:\ProgramData\Anaconda3\envs\py36\lib\site-packages\sqlalchemy\util\langhelpers.py", line 70, in __exit__
    with_traceback=exc_tb,
  File "D:\ProgramData\Anaconda3\envs\py36\lib\site-packages\sqlalchemy\util\compat.py", line 182, in raise_
    raise exception
  File "D:\ProgramData\Anaconda3\envs\py36\lib\site-packages\sqlalchemy\pool\impl.py", line 137, in _do_get
    return self._create_connection()
  File "D:\ProgramData\Anaconda3\envs\py36\lib\site-packages\sqlalchemy\pool\base.py", line 309, in _create_connection
    return _ConnectionRecord(self)
  File "D:\ProgramData\Anaconda3\envs\py36\lib\site-packages\sqlalchemy\pool\base.py", line 440, in __init__
    self.__connect(first_connect_check=True)
  File "D:\ProgramData\Anaconda3\envs\py36\lib\site-packages\sqlalchemy\pool\base.py", line 661, in __connect
    pool.logger.debug("Error on connect(): %s", e)
  File "D:\ProgramData\Anaconda3\envs\py36\lib\site-packages\sqlalchemy\util\langhelpers.py", line 70, in __exit__
    with_traceback=exc_tb,
  File "D:\ProgramData\Anaconda3\envs\py36\lib\site-packages\sqlalchemy\util\compat.py", line 182, in raise_
    raise exception
  File "D:\ProgramData\Anaconda3\envs\py36\lib\site-packages\sqlalchemy\pool\base.py", line 656, in __connect
    connection = pool._invoke_creator(self)
  File "D:\ProgramData\Anaconda3\envs\py36\lib\site-packages\sqlalchemy\engine\strategies.py", line 114, in connect
    return dialect.connect(*cargs, **cparams)
  File "D:\ProgramData\Anaconda3\envs\py36\lib\site-packages\sqlalchemy\engine\default.py", line 508, in connect
    return self.dbapi.connect(*cargs, **cparams)
  File "D:\ProgramData\Anaconda3\envs\py36\lib\site-packages\pymysql\connections.py", line 353, in __init__
    self.connect()
  File "D:\ProgramData\Anaconda3\envs\py36\lib\site-packages\pymysql\connections.py", line 664, in connect
    raise exc
sqlalchemy.exc.OperationalError: (pymysql.err.OperationalError) (2003, "Can't connect to MySQL server on '192.168.8.58' (timed out)")
(Background on this error at: http://sqlalche.me/e/13/e3q8)
ERROR:tornado.access:500 GET /login (192.168.2.89) 10009.88ms
ERROR:tornado.application:Uncaught exception GET /login (192.168.2.89)
HTTPServerRequest(protocol='http', host='192.168.2.89:8080', method='GET', uri='/login', version='HTTP/1.1', remote_ip='192.168.2.89')
Traceback (most recent call last):
  File "D:\ProgramData\Anaconda3\envs\py36\lib\site-packages\pymysql\connections.py", line 614, in connect
    (self.host, self.port), self.connect_timeout, **kwargs
  File "D:\ProgramData\Anaconda3\envs\py36\lib\socket.py", line 724, in create_connection
    raise err
  File "D:\ProgramData\Anaconda3\envs\py36\lib\socket.py", line 713, in create_connection
    sock.connect(sa)
socket.timeout: timed out

During handling of the above exception, another exception occurred:

Traceback (most recent call last):
  File "D:\ProgramData\Anaconda3\envs\py36\lib\site-packages\sqlalchemy\engine\base.py", line 2336, in _wrap_pool_connect
    return fn()
  File "D:\ProgramData\Anaconda3\envs\py36\lib\site-packages\sqlalchemy\pool\base.py", line 364, in connect
    return _ConnectionFairy._checkout(self)
  File "D:\ProgramData\Anaconda3\envs\py36\lib\site-packages\sqlalchemy\pool\base.py", line 778, in _checkout
    fairy = _ConnectionRecord.checkout(pool)
  File "D:\ProgramData\Anaconda3\envs\py36\lib\site-packages\sqlalchemy\pool\base.py", line 495, in checkout
    rec = pool._do_get()
  File "D:\ProgramData\Anaconda3\envs\py36\lib\site-packages\sqlalchemy\pool\impl.py", line 140, in _do_get
    self._dec_overflow()
  File "D:\ProgramData\Anaconda3\envs\py36\lib\site-packages\sqlalchemy\util\langhelpers.py", line 70, in __exit__
    with_traceback=exc_tb,
  File "D:\ProgramData\Anaconda3\envs\py36\lib\site-packages\sqlalchemy\util\compat.py", line 182, in raise_
    raise exception
  File "D:\ProgramData\Anaconda3\envs\py36\lib\site-packages\sqlalchemy\pool\impl.py", line 137, in _do_get
    return self._create_connection()
  File "D:\ProgramData\Anaconda3\envs\py36\lib\site-packages\sqlalchemy\pool\base.py", line 309, in _create_connection
    return _ConnectionRecord(self)
  File "D:\ProgramData\Anaconda3\envs\py36\lib\site-packages\sqlalchemy\pool\base.py", line 440, in __init__
    self.__connect(first_connect_check=True)
  File "D:\ProgramData\Anaconda3\envs\py36\lib\site-packages\sqlalchemy\pool\base.py", line 661, in __connect
    pool.logger.debug("Error on connect(): %s", e)
  File "D:\ProgramData\Anaconda3\envs\py36\lib\site-packages\sqlalchemy\util\langhelpers.py", line 70, in __exit__
    with_traceback=exc_tb,
  File "D:\ProgramData\Anaconda3\envs\py36\lib\site-packages\sqlalchemy\util\compat.py", line 182, in raise_
    raise exception
  File "D:\ProgramData\Anaconda3\envs\py36\lib\site-packages\sqlalchemy\pool\base.py", line 656, in __connect
    connection = pool._invoke_creator(self)
  File "D:\ProgramData\Anaconda3\envs\py36\lib\site-packages\sqlalchemy\engine\strategies.py", line 114, in connect
    return dialect.connect(*cargs, **cparams)
  File "D:\ProgramData\Anaconda3\envs\py36\lib\site-packages\sqlalchemy\engine\default.py", line 508, in connect
    return self.dbapi.connect(*cargs, **cparams)
  File "D:\ProgramData\Anaconda3\envs\py36\lib\site-packages\pymysql\connections.py", line 353, in __init__
    self.connect()
  File "D:\ProgramData\Anaconda3\envs\py36\lib\site-packages\pymysql\connections.py", line 664, in connect
    raise exc
pymysql.err.OperationalError: (2003, "Can't connect to MySQL server on '192.168.8.58' (timed out)")

The above exception was the direct cause of the following exception:

Traceback (most recent call last):
  File "D:\ProgramData\Anaconda3\envs\py36\lib\site-packages\tornado\web.py", line 1590, in _execute
    result = method(*self.path_args, **self.path_kwargs)
  File "C:\Users\Ð¡Æß\Desktop\MyTornado\handlers\public\loginhandle.py", line 21, in get
    user.open()
  File "C:\Users\Ð¡Æß\Desktop\MyTornado\handlers\public\sql_orm.py", line 38, in open
    Base.metadata.create_all(engine)
  File "D:\ProgramData\Anaconda3\envs\py36\lib\site-packages\sqlalchemy\sql\schema.py", line 4664, in create_all
    ddl.SchemaGenerator, self, checkfirst=checkfirst, tables=tables
  File "D:\ProgramData\Anaconda3\envs\py36\lib\site-packages\sqlalchemy\engine\base.py", line 2094, in _run_visitor
    with self._optional_conn_ctx_manager(connection) as conn:
  File "D:\ProgramData\Anaconda3\envs\py36\lib\contextlib.py", line 81, in __enter__
    return next(self.gen)
  File "D:\ProgramData\Anaconda3\envs\py36\lib\site-packages\sqlalchemy\engine\base.py", line 2086, in _optional_conn_ctx_manager
    with self._contextual_connect() as conn:
  File "D:\ProgramData\Anaconda3\envs\py36\lib\site-packages\sqlalchemy\engine\base.py", line 2302, in _contextual_connect
    self._wrap_pool_connect(self.pool.connect, None),
  File "D:\ProgramData\Anaconda3\envs\py36\lib\site-packages\sqlalchemy\engine\base.py", line 2340, in _wrap_pool_connect
    e, dialect, self
  File "D:\ProgramData\Anaconda3\envs\py36\lib\site-packages\sqlalchemy\engine\base.py", line 1584, in _handle_dbapi_exception_noconnection
    sqlalchemy_exception, with_traceback=exc_info[2], from_=e
  File "D:\ProgramData\Anaconda3\envs\py36\lib\site-packages\sqlalchemy\util\compat.py", line 182, in raise_
    raise exception
  File "D:\ProgramData\Anaconda3\envs\py36\lib\site-packages\sqlalchemy\engine\base.py", line 2336, in _wrap_pool_connect
    return fn()
  File "D:\ProgramData\Anaconda3\envs\py36\lib\site-packages\sqlalchemy\pool\base.py", line 364, in connect
    return _ConnectionFairy._checkout(self)
  File "D:\ProgramData\Anaconda3\envs\py36\lib\site-packages\sqlalchemy\pool\base.py", line 778, in _checkout
    fairy = _ConnectionRecord.checkout(pool)
  File "D:\ProgramData\Anaconda3\envs\py36\lib\site-packages\sqlalchemy\pool\base.py", line 495, in checkout
    rec = pool._do_get()
  File "D:\ProgramData\Anaconda3\envs\py36\lib\site-packages\sqlalchemy\pool\impl.py", line 140, in _do_get
    self._dec_overflow()
  File "D:\ProgramData\Anaconda3\envs\py36\lib\site-packages\sqlalchemy\util\langhelpers.py", line 70, in __exit__
    with_traceback=exc_tb,
  File "D:\ProgramData\Anaconda3\envs\py36\lib\site-packages\sqlalchemy\util\compat.py", line 182, in raise_
    raise exception
  File "D:\ProgramData\Anaconda3\envs\py36\lib\site-packages\sqlalchemy\pool\impl.py", line 137, in _do_get
    return self._create_connection()
  File "D:\ProgramData\Anaconda3\envs\py36\lib\site-packages\sqlalchemy\pool\base.py", line 309, in _create_connection
    return _ConnectionRecord(self)
  File "D:\ProgramData\Anaconda3\envs\py36\lib\site-packages\sqlalchemy\pool\base.py", line 440, in __init__
    self.__connect(first_connect_check=True)
  File "D:\ProgramData\Anaconda3\envs\py36\lib\site-packages\sqlalchemy\pool\base.py", line 661, in __connect
    pool.logger.debug("Error on connect(): %s", e)
  File "D:\ProgramData\Anaconda3\envs\py36\lib\site-packages\sqlalchemy\util\langhelpers.py", line 70, in __exit__
    with_traceback=exc_tb,
  File "D:\ProgramData\Anaconda3\envs\py36\lib\site-packages\sqlalchemy\util\compat.py", line 182, in raise_
    raise exception
  File "D:\ProgramData\Anaconda3\envs\py36\lib\site-packages\sqlalchemy\pool\base.py", line 656, in __connect
    connection = pool._invoke_creator(self)
  File "D:\ProgramData\Anaconda3\envs\py36\lib\site-packages\sqlalchemy\engine\strategies.py", line 114, in connect
    return dialect.connect(*cargs, **cparams)
  File "D:\ProgramData\Anaconda3\envs\py36\lib\site-packages\sqlalchemy\engine\default.py", line 508, in connect
    return self.dbapi.connect(*cargs, **cparams)
  File "D:\ProgramData\Anaconda3\envs\py36\lib\site-packages\pymysql\connections.py", line 353, in __init__
    self.connect()
  File "D:\ProgramData\Anaconda3\envs\py36\lib\site-packages\pymysql\connections.py", line 664, in connect
    raise exc
sqlalchemy.exc.OperationalError: (pymysql.err.OperationalError) (2003, "Can't connect to MySQL server on '192.168.8.58' (timed out)")
(Background on this error at: http://sqlalche.me/e/13/e3q8)
ERROR:tornado.access:500 GET /login (192.168.2.89) 10083.86ms
INFO:tornado.general:C:\Users\Ð¡Æß\Desktop\MyTornado\handlers\public\loginhandle.py modified; restarting server
ERROR:tornado.application:Uncaught exception GET /login (192.168.2.89)
HTTPServerRequest(protocol='http', host='192.168.2.89:8080', method='GET', uri='/login', version='HTTP/1.1', remote_ip='192.168.2.89')
Traceback (most recent call last):
  File "D:\ProgramData\Anaconda3\envs\py36\lib\site-packages\pymysql\connections.py", line 614, in connect
    (self.host, self.port), self.connect_timeout, **kwargs
  File "D:\ProgramData\Anaconda3\envs\py36\lib\socket.py", line 724, in create_connection
    raise err
  File "D:\ProgramData\Anaconda3\envs\py36\lib\socket.py", line 713, in create_connection
    sock.connect(sa)
socket.timeout: timed out

During handling of the above exception, another exception occurred:

Traceback (most recent call last):
  File "D:\ProgramData\Anaconda3\envs\py36\lib\site-packages\sqlalchemy\engine\base.py", line 2336, in _wrap_pool_connect
    return fn()
  File "D:\ProgramData\Anaconda3\envs\py36\lib\site-packages\sqlalchemy\pool\base.py", line 364, in connect
    return _ConnectionFairy._checkout(self)
  File "D:\ProgramData\Anaconda3\envs\py36\lib\site-packages\sqlalchemy\pool\base.py", line 778, in _checkout
    fairy = _ConnectionRecord.checkout(pool)
  File "D:\ProgramData\Anaconda3\envs\py36\lib\site-packages\sqlalchemy\pool\base.py", line 495, in checkout
    rec = pool._do_get()
  File "D:\ProgramData\Anaconda3\envs\py36\lib\site-packages\sqlalchemy\pool\impl.py", line 140, in _do_get
    self._dec_overflow()
  File "D:\ProgramData\Anaconda3\envs\py36\lib\site-packages\sqlalchemy\util\langhelpers.py", line 70, in __exit__
    with_traceback=exc_tb,
  File "D:\ProgramData\Anaconda3\envs\py36\lib\site-packages\sqlalchemy\util\compat.py", line 182, in raise_
    raise exception
  File "D:\ProgramData\Anaconda3\envs\py36\lib\site-packages\sqlalchemy\pool\impl.py", line 137, in _do_get
    return self._create_connection()
  File "D:\ProgramData\Anaconda3\envs\py36\lib\site-packages\sqlalchemy\pool\base.py", line 309, in _create_connection
    return _ConnectionRecord(self)
  File "D:\ProgramData\Anaconda3\envs\py36\lib\site-packages\sqlalchemy\pool\base.py", line 440, in __init__
    self.__connect(first_connect_check=True)
  File "D:\ProgramData\Anaconda3\envs\py36\lib\site-packages\sqlalchemy\pool\base.py", line 661, in __connect
    pool.logger.debug("Error on connect(): %s", e)
  File "D:\ProgramData\Anaconda3\envs\py36\lib\site-packages\sqlalchemy\util\langhelpers.py", line 70, in __exit__
    with_traceback=exc_tb,
  File "D:\ProgramData\Anaconda3\envs\py36\lib\site-packages\sqlalchemy\util\compat.py", line 182, in raise_
    raise exception
  File "D:\ProgramData\Anaconda3\envs\py36\lib\site-packages\sqlalchemy\pool\base.py", line 656, in __connect
    connection = pool._invoke_creator(self)
  File "D:\ProgramData\Anaconda3\envs\py36\lib\site-packages\sqlalchemy\engine\strategies.py", line 114, in connect
    return dialect.connect(*cargs, **cparams)
  File "D:\ProgramData\Anaconda3\envs\py36\lib\site-packages\sqlalchemy\engine\default.py", line 508, in connect
    return self.dbapi.connect(*cargs, **cparams)
  File "D:\ProgramData\Anaconda3\envs\py36\lib\site-packages\pymysql\connections.py", line 353, in __init__
    self.connect()
  File "D:\ProgramData\Anaconda3\envs\py36\lib\site-packages\pymysql\connections.py", line 664, in connect
    raise exc
pymysql.err.OperationalError: (2003, "Can't connect to MySQL server on '192.168.8.58' (timed out)")

The above exception was the direct cause of the following exception:

Traceback (most recent call last):
  File "D:\ProgramData\Anaconda3\envs\py36\lib\site-packages\tornado\web.py", line 1590, in _execute
    result = method(*self.path_args, **self.path_kwargs)
  File "C:\Users\Ð¡Æß\Desktop\MyTornado\handlers\public\loginhandle.py", line 21, in get
    user.open()
  File "C:\Users\Ð¡Æß\Desktop\MyTornado\handlers\public\sql_orm.py", line 38, in open
    Base.metadata.create_all(engine)
  File "D:\ProgramData\Anaconda3\envs\py36\lib\site-packages\sqlalchemy\sql\schema.py", line 4664, in create_all
    ddl.SchemaGenerator, self, checkfirst=checkfirst, tables=tables
  File "D:\ProgramData\Anaconda3\envs\py36\lib\site-packages\sqlalchemy\engine\base.py", line 2094, in _run_visitor
    with self._optional_conn_ctx_manager(connection) as conn:
  File "D:\ProgramData\Anaconda3\envs\py36\lib\contextlib.py", line 81, in __enter__
    return next(self.gen)
  File "D:\ProgramData\Anaconda3\envs\py36\lib\site-packages\sqlalchemy\engine\base.py", line 2086, in _optional_conn_ctx_manager
    with self._contextual_connect() as conn:
  File "D:\ProgramData\Anaconda3\envs\py36\lib\site-packages\sqlalchemy\engine\base.py", line 2302, in _contextual_connect
    self._wrap_pool_connect(self.pool.connect, None),
  File "D:\ProgramData\Anaconda3\envs\py36\lib\site-packages\sqlalchemy\engine\base.py", line 2340, in _wrap_pool_connect
    e, dialect, self
  File "D:\ProgramData\Anaconda3\envs\py36\lib\site-packages\sqlalchemy\engine\base.py", line 1584, in _handle_dbapi_exception_noconnection
    sqlalchemy_exception, with_traceback=exc_info[2], from_=e
  File "D:\ProgramData\Anaconda3\envs\py36\lib\site-packages\sqlalchemy\util\compat.py", line 182, in raise_
    raise exception
  File "D:\ProgramData\Anaconda3\envs\py36\lib\site-packages\sqlalchemy\engine\base.py", line 2336, in _wrap_pool_connect
    return fn()
  File "D:\ProgramData\Anaconda3\envs\py36\lib\site-packages\sqlalchemy\pool\base.py", line 364, in connect
    return _ConnectionFairy._checkout(self)
  File "D:\ProgramData\Anaconda3\envs\py36\lib\site-packages\sqlalchemy\pool\base.py", line 778, in _checkout
    fairy = _ConnectionRecord.checkout(pool)
  File "D:\ProgramData\Anaconda3\envs\py36\lib\site-packages\sqlalchemy\pool\base.py", line 495, in checkout
    rec = pool._do_get()
  File "D:\ProgramData\Anaconda3\envs\py36\lib\site-packages\sqlalchemy\pool\impl.py", line 140, in _do_get
    self._dec_overflow()
  File "D:\ProgramData\Anaconda3\envs\py36\lib\site-packages\sqlalchemy\util\langhelpers.py", line 70, in __exit__
    with_traceback=exc_tb,
  File "D:\ProgramData\Anaconda3\envs\py36\lib\site-packages\sqlalchemy\util\compat.py", line 182, in raise_
    raise exception
  File "D:\ProgramData\Anaconda3\envs\py36\lib\site-packages\sqlalchemy\pool\impl.py", line 137, in _do_get
    return self._create_connection()
  File "D:\ProgramData\Anaconda3\envs\py36\lib\site-packages\sqlalchemy\pool\base.py", line 309, in _create_connection
    return _ConnectionRecord(self)
  File "D:\ProgramData\Anaconda3\envs\py36\lib\site-packages\sqlalchemy\pool\base.py", line 440, in __init__
    self.__connect(first_connect_check=True)
  File "D:\ProgramData\Anaconda3\envs\py36\lib\site-packages\sqlalchemy\pool\base.py", line 661, in __connect
    pool.logger.debug("Error on connect(): %s", e)
  File "D:\ProgramData\Anaconda3\envs\py36\lib\site-packages\sqlalchemy\util\langhelpers.py", line 70, in __exit__
    with_traceback=exc_tb,
  File "D:\ProgramData\Anaconda3\envs\py36\lib\site-packages\sqlalchemy\util\compat.py", line 182, in raise_
    raise exception
  File "D:\ProgramData\Anaconda3\envs\py36\lib\site-packages\sqlalchemy\pool\base.py", line 656, in __connect
    connection = pool._invoke_creator(self)
  File "D:\ProgramData\Anaconda3\envs\py36\lib\site-packages\sqlalchemy\engine\strategies.py", line 114, in connect
    return dialect.connect(*cargs, **cparams)
  File "D:\ProgramData\Anaconda3\envs\py36\lib\site-packages\sqlalchemy\engine\default.py", line 508, in connect
    return self.dbapi.connect(*cargs, **cparams)
  File "D:\ProgramData\Anaconda3\envs\py36\lib\site-packages\pymysql\connections.py", line 353, in __init__
    self.connect()
  File "D:\ProgramData\Anaconda3\envs\py36\lib\site-packages\pymysql\connections.py", line 664, in connect
    raise exc
sqlalchemy.exc.OperationalError: (pymysql.err.OperationalError) (2003, "Can't connect to MySQL server on '192.168.8.58' (timed out)")
(Background on this error at: http://sqlalche.me/e/13/e3q8)
ERROR:tornado.access:500 GET /login (192.168.2.89) 10099.75ms
ERROR:tornado.application:Uncaught exception GET /login (192.168.2.89)
HTTPServerRequest(protocol='http', host='192.168.2.89:8080', method='GET', uri='/login', version='HTTP/1.1', remote_ip='192.168.2.89')
Traceback (most recent call last):
  File "D:\ProgramData\Anaconda3\envs\py36\lib\site-packages\pymysql\connections.py", line 614, in connect
    (self.host, self.port), self.connect_timeout, **kwargs
  File "D:\ProgramData\Anaconda3\envs\py36\lib\socket.py", line 724, in create_connection
    raise err
  File "D:\ProgramData\Anaconda3\envs\py36\lib\socket.py", line 713, in create_connection
    sock.connect(sa)
socket.timeout: timed out

During handling of the above exception, another exception occurred:

Traceback (most recent call last):
  File "D:\ProgramData\Anaconda3\envs\py36\lib\site-packages\sqlalchemy\engine\base.py", line 2336, in _wrap_pool_connect
    return fn()
  File "D:\ProgramData\Anaconda3\envs\py36\lib\site-packages\sqlalchemy\pool\base.py", line 364, in connect
    return _ConnectionFairy._checkout(self)
  File "D:\ProgramData\Anaconda3\envs\py36\lib\site-packages\sqlalchemy\pool\base.py", line 778, in _checkout
    fairy = _ConnectionRecord.checkout(pool)
  File "D:\ProgramData\Anaconda3\envs\py36\lib\site-packages\sqlalchemy\pool\base.py", line 495, in checkout
    rec = pool._do_get()
  File "D:\ProgramData\Anaconda3\envs\py36\lib\site-packages\sqlalchemy\pool\impl.py", line 140, in _do_get
    self._dec_overflow()
  File "D:\ProgramData\Anaconda3\envs\py36\lib\site-packages\sqlalchemy\util\langhelpers.py", line 70, in __exit__
    with_traceback=exc_tb,
  File "D:\ProgramData\Anaconda3\envs\py36\lib\site-packages\sqlalchemy\util\compat.py", line 182, in raise_
    raise exception
  File "D:\ProgramData\Anaconda3\envs\py36\lib\site-packages\sqlalchemy\pool\impl.py", line 137, in _do_get
    return self._create_connection()
  File "D:\ProgramData\Anaconda3\envs\py36\lib\site-packages\sqlalchemy\pool\base.py", line 309, in _create_connection
    return _ConnectionRecord(self)
  File "D:\ProgramData\Anaconda3\envs\py36\lib\site-packages\sqlalchemy\pool\base.py", line 440, in __init__
    self.__connect(first_connect_check=True)
  File "D:\ProgramData\Anaconda3\envs\py36\lib\site-packages\sqlalchemy\pool\base.py", line 661, in __connect
    pool.logger.debug("Error on connect(): %s", e)
  File "D:\ProgramData\Anaconda3\envs\py36\lib\site-packages\sqlalchemy\util\langhelpers.py", line 70, in __exit__
    with_traceback=exc_tb,
  File "D:\ProgramData\Anaconda3\envs\py36\lib\site-packages\sqlalchemy\util\compat.py", line 182, in raise_
    raise exception
  File "D:\ProgramData\Anaconda3\envs\py36\lib\site-packages\sqlalchemy\pool\base.py", line 656, in __connect
    connection = pool._invoke_creator(self)
  File "D:\ProgramData\Anaconda3\envs\py36\lib\site-packages\sqlalchemy\engine\strategies.py", line 114, in connect
    return dialect.connect(*cargs, **cparams)
  File "D:\ProgramData\Anaconda3\envs\py36\lib\site-packages\sqlalchemy\engine\default.py", line 508, in connect
    return self.dbapi.connect(*cargs, **cparams)
  File "D:\ProgramData\Anaconda3\envs\py36\lib\site-packages\pymysql\connections.py", line 353, in __init__
    self.connect()
  File "D:\ProgramData\Anaconda3\envs\py36\lib\site-packages\pymysql\connections.py", line 664, in connect
    raise exc
pymysql.err.OperationalError: (2003, "Can't connect to MySQL server on '192.168.8.58' (timed out)")

The above exception was the direct cause of the following exception:

Traceback (most recent call last):
  File "D:\ProgramData\Anaconda3\envs\py36\lib\site-packages\tornado\web.py", line 1590, in _execute
    result = method(*self.path_args, **self.path_kwargs)
  File "C:\Users\Ð¡Æß\Desktop\MyTornado\handlers\public\loginhandle.py", line 21, in get
    user.open()
  File "C:\Users\Ð¡Æß\Desktop\MyTornado\handlers\public\sql_orm.py", line 38, in open
    Base.metadata.create_all(engine)
  File "D:\ProgramData\Anaconda3\envs\py36\lib\site-packages\sqlalchemy\sql\schema.py", line 4664, in create_all
    ddl.SchemaGenerator, self, checkfirst=checkfirst, tables=tables
  File "D:\ProgramData\Anaconda3\envs\py36\lib\site-packages\sqlalchemy\engine\base.py", line 2094, in _run_visitor
    with self._optional_conn_ctx_manager(connection) as conn:
  File "D:\ProgramData\Anaconda3\envs\py36\lib\contextlib.py", line 81, in __enter__
    return next(self.gen)
  File "D:\ProgramData\Anaconda3\envs\py36\lib\site-packages\sqlalchemy\engine\base.py", line 2086, in _optional_conn_ctx_manager
    with self._contextual_connect() as conn:
  File "D:\ProgramData\Anaconda3\envs\py36\lib\site-packages\sqlalchemy\engine\base.py", line 2302, in _contextual_connect
    self._wrap_pool_connect(self.pool.connect, None),
  File "D:\ProgramData\Anaconda3\envs\py36\lib\site-packages\sqlalchemy\engine\base.py", line 2340, in _wrap_pool_connect
    e, dialect, self
  File "D:\ProgramData\Anaconda3\envs\py36\lib\site-packages\sqlalchemy\engine\base.py", line 1584, in _handle_dbapi_exception_noconnection
    sqlalchemy_exception, with_traceback=exc_info[2], from_=e
  File "D:\ProgramData\Anaconda3\envs\py36\lib\site-packages\sqlalchemy\util\compat.py", line 182, in raise_
    raise exception
  File "D:\ProgramData\Anaconda3\envs\py36\lib\site-packages\sqlalchemy\engine\base.py", line 2336, in _wrap_pool_connect
    return fn()
  File "D:\ProgramData\Anaconda3\envs\py36\lib\site-packages\sqlalchemy\pool\base.py", line 364, in connect
    return _ConnectionFairy._checkout(self)
  File "D:\ProgramData\Anaconda3\envs\py36\lib\site-packages\sqlalchemy\pool\base.py", line 778, in _checkout
    fairy = _ConnectionRecord.checkout(pool)
  File "D:\ProgramData\Anaconda3\envs\py36\lib\site-packages\sqlalchemy\pool\base.py", line 495, in checkout
    rec = pool._do_get()
  File "D:\ProgramData\Anaconda3\envs\py36\lib\site-packages\sqlalchemy\pool\impl.py", line 140, in _do_get
    self._dec_overflow()
  File "D:\ProgramData\Anaconda3\envs\py36\lib\site-packages\sqlalchemy\util\langhelpers.py", line 70, in __exit__
    with_traceback=exc_tb,
  File "D:\ProgramData\Anaconda3\envs\py36\lib\site-packages\sqlalchemy\util\compat.py", line 182, in raise_
    raise exception
  File "D:\ProgramData\Anaconda3\envs\py36\lib\site-packages\sqlalchemy\pool\impl.py", line 137, in _do_get
    return self._create_connection()
  File "D:\ProgramData\Anaconda3\envs\py36\lib\site-packages\sqlalchemy\pool\base.py", line 309, in _create_connection
    return _ConnectionRecord(self)
  File "D:\ProgramData\Anaconda3\envs\py36\lib\site-packages\sqlalchemy\pool\base.py", line 440, in __init__
    self.__connect(first_connect_check=True)
  File "D:\ProgramData\Anaconda3\envs\py36\lib\site-packages\sqlalchemy\pool\base.py", line 661, in __connect
    pool.logger.debug("Error on connect(): %s", e)
  File "D:\ProgramData\Anaconda3\envs\py36\lib\site-packages\sqlalchemy\util\langhelpers.py", line 70, in __exit__
    with_traceback=exc_tb,
  File "D:\ProgramData\Anaconda3\envs\py36\lib\site-packages\sqlalchemy\util\compat.py", line 182, in raise_
    raise exception
  File "D:\ProgramData\Anaconda3\envs\py36\lib\site-packages\sqlalchemy\pool\base.py", line 656, in __connect
    connection = pool._invoke_creator(self)
  File "D:\ProgramData\Anaconda3\envs\py36\lib\site-packages\sqlalchemy\engine\strategies.py", line 114, in connect
    return dialect.connect(*cargs, **cparams)
  File "D:\ProgramData\Anaconda3\envs\py36\lib\site-packages\sqlalchemy\engine\default.py", line 508, in connect
    return self.dbapi.connect(*cargs, **cparams)
  File "D:\ProgramData\Anaconda3\envs\py36\lib\site-packages\pymysql\connections.py", line 353, in __init__
    self.connect()
  File "D:\ProgramData\Anaconda3\envs\py36\lib\site-packages\pymysql\connections.py", line 664, in connect
    raise exc
sqlalchemy.exc.OperationalError: (pymysql.err.OperationalError) (2003, "Can't connect to MySQL server on '192.168.8.58' (timed out)")
(Background on this error at: http://sqlalche.me/e/13/e3q8)
ERROR:tornado.access:500 GET /login (192.168.2.89) 10020.94ms
ERROR:tornado.application:Uncaught exception GET /login (192.168.2.89)
HTTPServerRequest(protocol='http', host='192.168.2.89:8080', method='GET', uri='/login', version='HTTP/1.1', remote_ip='192.168.2.89')
Traceback (most recent call last):
  File "D:\ProgramData\Anaconda3\envs\py36\lib\site-packages\pymysql\connections.py", line 614, in connect
    (self.host, self.port), self.connect_timeout, **kwargs
  File "D:\ProgramData\Anaconda3\envs\py36\lib\socket.py", line 724, in create_connection
    raise err
  File "D:\ProgramData\Anaconda3\envs\py36\lib\socket.py", line 713, in create_connection
    sock.connect(sa)
socket.timeout: timed out

During handling of the above exception, another exception occurred:

Traceback (most recent call last):
  File "D:\ProgramData\Anaconda3\envs\py36\lib\site-packages\sqlalchemy\engine\base.py", line 2336, in _wrap_pool_connect
    return fn()
  File "D:\ProgramData\Anaconda3\envs\py36\lib\site-packages\sqlalchemy\pool\base.py", line 364, in connect
    return _ConnectionFairy._checkout(self)
  File "D:\ProgramData\Anaconda3\envs\py36\lib\site-packages\sqlalchemy\pool\base.py", line 778, in _checkout
    fairy = _ConnectionRecord.checkout(pool)
  File "D:\ProgramData\Anaconda3\envs\py36\lib\site-packages\sqlalchemy\pool\base.py", line 495, in checkout
    rec = pool._do_get()
  File "D:\ProgramData\Anaconda3\envs\py36\lib\site-packages\sqlalchemy\pool\impl.py", line 140, in _do_get
    self._dec_overflow()
  File "D:\ProgramData\Anaconda3\envs\py36\lib\site-packages\sqlalchemy\util\langhelpers.py", line 70, in __exit__
    with_traceback=exc_tb,
  File "D:\ProgramData\Anaconda3\envs\py36\lib\site-packages\sqlalchemy\util\compat.py", line 182, in raise_
    raise exception
  File "D:\ProgramData\Anaconda3\envs\py36\lib\site-packages\sqlalchemy\pool\impl.py", line 137, in _do_get
    return self._create_connection()
  File "D:\ProgramData\Anaconda3\envs\py36\lib\site-packages\sqlalchemy\pool\base.py", line 309, in _create_connection
    return _ConnectionRecord(self)
  File "D:\ProgramData\Anaconda3\envs\py36\lib\site-packages\sqlalchemy\pool\base.py", line 440, in __init__
    self.__connect(first_connect_check=True)
  File "D:\ProgramData\Anaconda3\envs\py36\lib\site-packages\sqlalchemy\pool\base.py", line 661, in __connect
    pool.logger.debug("Error on connect(): %s", e)
  File "D:\ProgramData\Anaconda3\envs\py36\lib\site-packages\sqlalchemy\util\langhelpers.py", line 70, in __exit__
    with_traceback=exc_tb,
  File "D:\ProgramData\Anaconda3\envs\py36\lib\site-packages\sqlalchemy\util\compat.py", line 182, in raise_
    raise exception
  File "D:\ProgramData\Anaconda3\envs\py36\lib\site-packages\sqlalchemy\pool\base.py", line 656, in __connect
    connection = pool._invoke_creator(self)
  File "D:\ProgramData\Anaconda3\envs\py36\lib\site-packages\sqlalchemy\engine\strategies.py", line 114, in connect
    return dialect.connect(*cargs, **cparams)
  File "D:\ProgramData\Anaconda3\envs\py36\lib\site-packages\sqlalchemy\engine\default.py", line 508, in connect
    return self.dbapi.connect(*cargs, **cparams)
  File "D:\ProgramData\Anaconda3\envs\py36\lib\site-packages\pymysql\connections.py", line 353, in __init__
    self.connect()
  File "D:\ProgramData\Anaconda3\envs\py36\lib\site-packages\pymysql\connections.py", line 664, in connect
    raise exc
pymysql.err.OperationalError: (2003, "Can't connect to MySQL server on '192.168.8.58' (timed out)")

The above exception was the direct cause of the following exception:

Traceback (most recent call last):
  File "D:\ProgramData\Anaconda3\envs\py36\lib\site-packages\tornado\web.py", line 1590, in _execute
    result = method(*self.path_args, **self.path_kwargs)
  File "C:\Users\Ð¡Æß\Desktop\MyTornado\handlers\public\loginhandle.py", line 21, in get
    user.open()
  File "C:\Users\Ð¡Æß\Desktop\MyTornado\handlers\public\sql_orm.py", line 38, in open
    Base.metadata.create_all(engine)
  File "D:\ProgramData\Anaconda3\envs\py36\lib\site-packages\sqlalchemy\sql\schema.py", line 4664, in create_all
    ddl.SchemaGenerator, self, checkfirst=checkfirst, tables=tables
  File "D:\ProgramData\Anaconda3\envs\py36\lib\site-packages\sqlalchemy\engine\base.py", line 2094, in _run_visitor
    with self._optional_conn_ctx_manager(connection) as conn:
  File "D:\ProgramData\Anaconda3\envs\py36\lib\contextlib.py", line 81, in __enter__
    return next(self.gen)
  File "D:\ProgramData\Anaconda3\envs\py36\lib\site-packages\sqlalchemy\engine\base.py", line 2086, in _optional_conn_ctx_manager
    with self._contextual_connect() as conn:
  File "D:\ProgramData\Anaconda3\envs\py36\lib\site-packages\sqlalchemy\engine\base.py", line 2302, in _contextual_connect
    self._wrap_pool_connect(self.pool.connect, None),
  File "D:\ProgramData\Anaconda3\envs\py36\lib\site-packages\sqlalchemy\engine\base.py", line 2340, in _wrap_pool_connect
    e, dialect, self
  File "D:\ProgramData\Anaconda3\envs\py36\lib\site-packages\sqlalchemy\engine\base.py", line 1584, in _handle_dbapi_exception_noconnection
    sqlalchemy_exception, with_traceback=exc_info[2], from_=e
  File "D:\ProgramData\Anaconda3\envs\py36\lib\site-packages\sqlalchemy\util\compat.py", line 182, in raise_
    raise exception
  File "D:\ProgramData\Anaconda3\envs\py36\lib\site-packages\sqlalchemy\engine\base.py", line 2336, in _wrap_pool_connect
    return fn()
  File "D:\ProgramData\Anaconda3\envs\py36\lib\site-packages\sqlalchemy\pool\base.py", line 364, in connect
    return _ConnectionFairy._checkout(self)
  File "D:\ProgramData\Anaconda3\envs\py36\lib\site-packages\sqlalchemy\pool\base.py", line 778, in _checkout
    fairy = _ConnectionRecord.checkout(pool)
  File "D:\ProgramData\Anaconda3\envs\py36\lib\site-packages\sqlalchemy\pool\base.py", line 495, in checkout
    rec = pool._do_get()
  File "D:\ProgramData\Anaconda3\envs\py36\lib\site-packages\sqlalchemy\pool\impl.py", line 140, in _do_get
    self._dec_overflow()
  File "D:\ProgramData\Anaconda3\envs\py36\lib\site-packages\sqlalchemy\util\langhelpers.py", line 70, in __exit__
    with_traceback=exc_tb,
  File "D:\ProgramData\Anaconda3\envs\py36\lib\site-packages\sqlalchemy\util\compat.py", line 182, in raise_
    raise exception
  File "D:\ProgramData\Anaconda3\envs\py36\lib\site-packages\sqlalchemy\pool\impl.py", line 137, in _do_get
    return self._create_connection()
  File "D:\ProgramData\Anaconda3\envs\py36\lib\site-packages\sqlalchemy\pool\base.py", line 309, in _create_connection
    return _ConnectionRecord(self)
  File "D:\ProgramData\Anaconda3\envs\py36\lib\site-packages\sqlalchemy\pool\base.py", line 440, in __init__
    self.__connect(first_connect_check=True)
  File "D:\ProgramData\Anaconda3\envs\py36\lib\site-packages\sqlalchemy\pool\base.py", line 661, in __connect
    pool.logger.debug("Error on connect(): %s", e)
  File "D:\ProgramData\Anaconda3\envs\py36\lib\site-packages\sqlalchemy\util\langhelpers.py", line 70, in __exit__
    with_traceback=exc_tb,
  File "D:\ProgramData\Anaconda3\envs\py36\lib\site-packages\sqlalchemy\util\compat.py", line 182, in raise_
    raise exception
  File "D:\ProgramData\Anaconda3\envs\py36\lib\site-packages\sqlalchemy\pool\base.py", line 656, in __connect
    connection = pool._invoke_creator(self)
  File "D:\ProgramData\Anaconda3\envs\py36\lib\site-packages\sqlalchemy\engine\strategies.py", line 114, in connect
    return dialect.connect(*cargs, **cparams)
  File "D:\ProgramData\Anaconda3\envs\py36\lib\site-packages\sqlalchemy\engine\default.py", line 508, in connect
    return self.dbapi.connect(*cargs, **cparams)
  File "D:\ProgramData\Anaconda3\envs\py36\lib\site-packages\pymysql\connections.py", line 353, in __init__
    self.connect()
  File "D:\ProgramData\Anaconda3\envs\py36\lib\site-packages\pymysql\connections.py", line 664, in connect
    raise exc
sqlalchemy.exc.OperationalError: (pymysql.err.OperationalError) (2003, "Can't connect to MySQL server on '192.168.8.58' (timed out)")
(Background on this error at: http://sqlalche.me/e/13/e3q8)
ERROR:tornado.access:500 GET /login (192.168.2.89) 10092.94ms
ERROR:tornado.application:Uncaught exception GET /login (127.0.0.1)
HTTPServerRequest(protocol='http', host='127.0.0.1:8080', method='GET', uri='/login', version='HTTP/1.1', remote_ip='127.0.0.1')
Traceback (most recent call last):
  File "D:\ProgramData\Anaconda3\envs\py36\lib\site-packages\pymysql\connections.py", line 614, in connect
    (self.host, self.port), self.connect_timeout, **kwargs
  File "D:\ProgramData\Anaconda3\envs\py36\lib\socket.py", line 724, in create_connection
    raise err
  File "D:\ProgramData\Anaconda3\envs\py36\lib\socket.py", line 713, in create_connection
    sock.connect(sa)
socket.timeout: timed out

During handling of the above exception, another exception occurred:

Traceback (most recent call last):
  File "D:\ProgramData\Anaconda3\envs\py36\lib\site-packages\sqlalchemy\engine\base.py", line 2336, in _wrap_pool_connect
    return fn()
  File "D:\ProgramData\Anaconda3\envs\py36\lib\site-packages\sqlalchemy\pool\base.py", line 364, in connect
    return _ConnectionFairy._checkout(self)
  File "D:\ProgramData\Anaconda3\envs\py36\lib\site-packages\sqlalchemy\pool\base.py", line 778, in _checkout
    fairy = _ConnectionRecord.checkout(pool)
  File "D:\ProgramData\Anaconda3\envs\py36\lib\site-packages\sqlalchemy\pool\base.py", line 495, in checkout
    rec = pool._do_get()
  File "D:\ProgramData\Anaconda3\envs\py36\lib\site-packages\sqlalchemy\pool\impl.py", line 140, in _do_get
    self._dec_overflow()
  File "D:\ProgramData\Anaconda3\envs\py36\lib\site-packages\sqlalchemy\util\langhelpers.py", line 70, in __exit__
    with_traceback=exc_tb,
  File "D:\ProgramData\Anaconda3\envs\py36\lib\site-packages\sqlalchemy\util\compat.py", line 182, in raise_
    raise exception
  File "D:\ProgramData\Anaconda3\envs\py36\lib\site-packages\sqlalchemy\pool\impl.py", line 137, in _do_get
    return self._create_connection()
  File "D:\ProgramData\Anaconda3\envs\py36\lib\site-packages\sqlalchemy\pool\base.py", line 309, in _create_connection
    return _ConnectionRecord(self)
  File "D:\ProgramData\Anaconda3\envs\py36\lib\site-packages\sqlalchemy\pool\base.py", line 440, in __init__
    self.__connect(first_connect_check=True)
  File "D:\ProgramData\Anaconda3\envs\py36\lib\site-packages\sqlalchemy\pool\base.py", line 661, in __connect
    pool.logger.debug("Error on connect(): %s", e)
  File "D:\ProgramData\Anaconda3\envs\py36\lib\site-packages\sqlalchemy\util\langhelpers.py", line 70, in __exit__
    with_traceback=exc_tb,
  File "D:\ProgramData\Anaconda3\envs\py36\lib\site-packages\sqlalchemy\util\compat.py", line 182, in raise_
    raise exception
  File "D:\ProgramData\Anaconda3\envs\py36\lib\site-packages\sqlalchemy\pool\base.py", line 656, in __connect
    connection = pool._invoke_creator(self)
  File "D:\ProgramData\Anaconda3\envs\py36\lib\site-packages\sqlalchemy\engine\strategies.py", line 114, in connect
    return dialect.connect(*cargs, **cparams)
  File "D:\ProgramData\Anaconda3\envs\py36\lib\site-packages\sqlalchemy\engine\default.py", line 508, in connect
    return self.dbapi.connect(*cargs, **cparams)
  File "D:\ProgramData\Anaconda3\envs\py36\lib\site-packages\pymysql\connections.py", line 353, in __init__
    self.connect()
  File "D:\ProgramData\Anaconda3\envs\py36\lib\site-packages\pymysql\connections.py", line 664, in connect
    raise exc
pymysql.err.OperationalError: (2003, "Can't connect to MySQL server on '192.168.8.58' (timed out)")

The above exception was the direct cause of the following exception:

Traceback (most recent call last):
  File "D:\ProgramData\Anaconda3\envs\py36\lib\site-packages\tornado\web.py", line 1590, in _execute
    result = method(*self.path_args, **self.path_kwargs)
  File "C:\Users\Ð¡Æß\Desktop\MyTornado\handlers\public\loginhandle.py", line 21, in get
    user.open()
  File "C:\Users\Ð¡Æß\Desktop\MyTornado\handlers\public\sql_orm.py", line 38, in open
    Base.metadata.create_all(engine)
  File "D:\ProgramData\Anaconda3\envs\py36\lib\site-packages\sqlalchemy\sql\schema.py", line 4664, in create_all
    ddl.SchemaGenerator, self, checkfirst=checkfirst, tables=tables
  File "D:\ProgramData\Anaconda3\envs\py36\lib\site-packages\sqlalchemy\engine\base.py", line 2094, in _run_visitor
    with self._optional_conn_ctx_manager(connection) as conn:
  File "D:\ProgramData\Anaconda3\envs\py36\lib\contextlib.py", line 81, in __enter__
    return next(self.gen)
  File "D:\ProgramData\Anaconda3\envs\py36\lib\site-packages\sqlalchemy\engine\base.py", line 2086, in _optional_conn_ctx_manager
    with self._contextual_connect() as conn:
  File "D:\ProgramData\Anaconda3\envs\py36\lib\site-packages\sqlalchemy\engine\base.py", line 2302, in _contextual_connect
    self._wrap_pool_connect(self.pool.connect, None),
  File "D:\ProgramData\Anaconda3\envs\py36\lib\site-packages\sqlalchemy\engine\base.py", line 2340, in _wrap_pool_connect
    e, dialect, self
  File "D:\ProgramData\Anaconda3\envs\py36\lib\site-packages\sqlalchemy\engine\base.py", line 1584, in _handle_dbapi_exception_noconnection
    sqlalchemy_exception, with_traceback=exc_info[2], from_=e
  File "D:\ProgramData\Anaconda3\envs\py36\lib\site-packages\sqlalchemy\util\compat.py", line 182, in raise_
    raise exception
  File "D:\ProgramData\Anaconda3\envs\py36\lib\site-packages\sqlalchemy\engine\base.py", line 2336, in _wrap_pool_connect
    return fn()
  File "D:\ProgramData\Anaconda3\envs\py36\lib\site-packages\sqlalchemy\pool\base.py", line 364, in connect
    return _ConnectionFairy._checkout(self)
  File "D:\ProgramData\Anaconda3\envs\py36\lib\site-packages\sqlalchemy\pool\base.py", line 778, in _checkout
    fairy = _ConnectionRecord.checkout(pool)
  File "D:\ProgramData\Anaconda3\envs\py36\lib\site-packages\sqlalchemy\pool\base.py", line 495, in checkout
    rec = pool._do_get()
  File "D:\ProgramData\Anaconda3\envs\py36\lib\site-packages\sqlalchemy\pool\impl.py", line 140, in _do_get
    self._dec_overflow()
  File "D:\ProgramData\Anaconda3\envs\py36\lib\site-packages\sqlalchemy\util\langhelpers.py", line 70, in __exit__
    with_traceback=exc_tb,
  File "D:\ProgramData\Anaconda3\envs\py36\lib\site-packages\sqlalchemy\util\compat.py", line 182, in raise_
    raise exception
  File "D:\ProgramData\Anaconda3\envs\py36\lib\site-packages\sqlalchemy\pool\impl.py", line 137, in _do_get
    return self._create_connection()
  File "D:\ProgramData\Anaconda3\envs\py36\lib\site-packages\sqlalchemy\pool\base.py", line 309, in _create_connection
    return _ConnectionRecord(self)
  File "D:\ProgramData\Anaconda3\envs\py36\lib\site-packages\sqlalchemy\pool\base.py", line 440, in __init__
    self.__connect(first_connect_check=True)
  File "D:\ProgramData\Anaconda3\envs\py36\lib\site-packages\sqlalchemy\pool\base.py", line 661, in __connect
    pool.logger.debug("Error on connect(): %s", e)
  File "D:\ProgramData\Anaconda3\envs\py36\lib\site-packages\sqlalchemy\util\langhelpers.py", line 70, in __exit__
    with_traceback=exc_tb,
  File "D:\ProgramData\Anaconda3\envs\py36\lib\site-packages\sqlalchemy\util\compat.py", line 182, in raise_
    raise exception
  File "D:\ProgramData\Anaconda3\envs\py36\lib\site-packages\sqlalchemy\pool\base.py", line 656, in __connect
    connection = pool._invoke_creator(self)
  File "D:\ProgramData\Anaconda3\envs\py36\lib\site-packages\sqlalchemy\engine\strategies.py", line 114, in connect
    return dialect.connect(*cargs, **cparams)
  File "D:\ProgramData\Anaconda3\envs\py36\lib\site-packages\sqlalchemy\engine\default.py", line 508, in connect
    return self.dbapi.connect(*cargs, **cparams)
  File "D:\ProgramData\Anaconda3\envs\py36\lib\site-packages\pymysql\connections.py", line 353, in __init__
    self.connect()
  File "D:\ProgramData\Anaconda3\envs\py36\lib\site-packages\pymysql\connections.py", line 664, in connect
    raise exc
sqlalchemy.exc.OperationalError: (pymysql.err.OperationalError) (2003, "Can't connect to MySQL server on '192.168.8.58' (timed out)")
(Background on this error at: http://sqlalche.me/e/13/e3q8)
ERROR:tornado.access:500 GET /login (127.0.0.1) 10006.15ms
WARNING:tornado.access:404 GET /favicon.ico (127.0.0.1) 3.00ms
ERROR:tornado.application:Uncaught exception GET /login?username=liubin&password=123456 (127.0.0.1)
HTTPServerRequest(protocol='http', host='localhost:8080', method='GET', uri='/login?username=liubin&password=123456', version='HTTP/1.1', remote_ip='127.0.0.1')
Traceback (most recent call last):
  File "D:\ProgramData\Anaconda3\envs\py36\lib\site-packages\pymysql\connections.py", line 614, in connect
    (self.host, self.port), self.connect_timeout, **kwargs
  File "D:\ProgramData\Anaconda3\envs\py36\lib\socket.py", line 724, in create_connection
    raise err
  File "D:\ProgramData\Anaconda3\envs\py36\lib\socket.py", line 713, in create_connection
    sock.connect(sa)
socket.timeout: timed out

During handling of the above exception, another exception occurred:

Traceback (most recent call last):
  File "D:\ProgramData\Anaconda3\envs\py36\lib\site-packages\sqlalchemy\engine\base.py", line 2336, in _wrap_pool_connect
    return fn()
  File "D:\ProgramData\Anaconda3\envs\py36\lib\site-packages\sqlalchemy\pool\base.py", line 364, in connect
    return _ConnectionFairy._checkout(self)
  File "D:\ProgramData\Anaconda3\envs\py36\lib\site-packages\sqlalchemy\pool\base.py", line 778, in _checkout
    fairy = _ConnectionRecord.checkout(pool)
  File "D:\ProgramData\Anaconda3\envs\py36\lib\site-packages\sqlalchemy\pool\base.py", line 495, in checkout
    rec = pool._do_get()
  File "D:\ProgramData\Anaconda3\envs\py36\lib\site-packages\sqlalchemy\pool\impl.py", line 140, in _do_get
    self._dec_overflow()
  File "D:\ProgramData\Anaconda3\envs\py36\lib\site-packages\sqlalchemy\util\langhelpers.py", line 70, in __exit__
    with_traceback=exc_tb,
  File "D:\ProgramData\Anaconda3\envs\py36\lib\site-packages\sqlalchemy\util\compat.py", line 182, in raise_
    raise exception
  File "D:\ProgramData\Anaconda3\envs\py36\lib\site-packages\sqlalchemy\pool\impl.py", line 137, in _do_get
    return self._create_connection()
  File "D:\ProgramData\Anaconda3\envs\py36\lib\site-packages\sqlalchemy\pool\base.py", line 309, in _create_connection
    return _ConnectionRecord(self)
  File "D:\ProgramData\Anaconda3\envs\py36\lib\site-packages\sqlalchemy\pool\base.py", line 440, in __init__
    self.__connect(first_connect_check=True)
  File "D:\ProgramData\Anaconda3\envs\py36\lib\site-packages\sqlalchemy\pool\base.py", line 661, in __connect
    pool.logger.debug("Error on connect(): %s", e)
  File "D:\ProgramData\Anaconda3\envs\py36\lib\site-packages\sqlalchemy\util\langhelpers.py", line 70, in __exit__
    with_traceback=exc_tb,
  File "D:\ProgramData\Anaconda3\envs\py36\lib\site-packages\sqlalchemy\util\compat.py", line 182, in raise_
    raise exception
  File "D:\ProgramData\Anaconda3\envs\py36\lib\site-packages\sqlalchemy\pool\base.py", line 656, in __connect
    connection = pool._invoke_creator(self)
  File "D:\ProgramData\Anaconda3\envs\py36\lib\site-packages\sqlalchemy\engine\strategies.py", line 114, in connect
    return dialect.connect(*cargs, **cparams)
  File "D:\ProgramData\Anaconda3\envs\py36\lib\site-packages\sqlalchemy\engine\default.py", line 508, in connect
    return self.dbapi.connect(*cargs, **cparams)
  File "D:\ProgramData\Anaconda3\envs\py36\lib\site-packages\pymysql\connections.py", line 353, in __init__
    self.connect()
  File "D:\ProgramData\Anaconda3\envs\py36\lib\site-packages\pymysql\connections.py", line 664, in connect
    raise exc
pymysql.err.OperationalError: (2003, "Can't connect to MySQL server on '192.168.8.58' (timed out)")

The above exception was the direct cause of the following exception:

Traceback (most recent call last):
  File "D:\ProgramData\Anaconda3\envs\py36\lib\site-packages\tornado\web.py", line 1590, in _execute
    result = method(*self.path_args, **self.path_kwargs)
  File "C:\Users\Ð¡Æß\Desktop\MyTornado\handlers\public\loginhandle.py", line 21, in get
    user.open()
  File "C:\Users\Ð¡Æß\Desktop\MyTornado\handlers\public\sql_orm.py", line 38, in open
    Base.metadata.create_all(engine)
  File "D:\ProgramData\Anaconda3\envs\py36\lib\site-packages\sqlalchemy\sql\schema.py", line 4664, in create_all
    ddl.SchemaGenerator, self, checkfirst=checkfirst, tables=tables
  File "D:\ProgramData\Anaconda3\envs\py36\lib\site-packages\sqlalchemy\engine\base.py", line 2094, in _run_visitor
    with self._optional_conn_ctx_manager(connection) as conn:
  File "D:\ProgramData\Anaconda3\envs\py36\lib\contextlib.py", line 81, in __enter__
    return next(self.gen)
  File "D:\ProgramData\Anaconda3\envs\py36\lib\site-packages\sqlalchemy\engine\base.py", line 2086, in _optional_conn_ctx_manager
    with self._contextual_connect() as conn:
  File "D:\ProgramData\Anaconda3\envs\py36\lib\site-packages\sqlalchemy\engine\base.py", line 2302, in _contextual_connect
    self._wrap_pool_connect(self.pool.connect, None),
  File "D:\ProgramData\Anaconda3\envs\py36\lib\site-packages\sqlalchemy\engine\base.py", line 2340, in _wrap_pool_connect
    e, dialect, self
  File "D:\ProgramData\Anaconda3\envs\py36\lib\site-packages\sqlalchemy\engine\base.py", line 1584, in _handle_dbapi_exception_noconnection
    sqlalchemy_exception, with_traceback=exc_info[2], from_=e
  File "D:\ProgramData\Anaconda3\envs\py36\lib\site-packages\sqlalchemy\util\compat.py", line 182, in raise_
    raise exception
  File "D:\ProgramData\Anaconda3\envs\py36\lib\site-packages\sqlalchemy\engine\base.py", line 2336, in _wrap_pool_connect
    return fn()
  File "D:\ProgramData\Anaconda3\envs\py36\lib\site-packages\sqlalchemy\pool\base.py", line 364, in connect
    return _ConnectionFairy._checkout(self)
  File "D:\ProgramData\Anaconda3\envs\py36\lib\site-packages\sqlalchemy\pool\base.py", line 778, in _checkout
    fairy = _ConnectionRecord.checkout(pool)
  File "D:\ProgramData\Anaconda3\envs\py36\lib\site-packages\sqlalchemy\pool\base.py", line 495, in checkout
    rec = pool._do_get()
  File "D:\ProgramData\Anaconda3\envs\py36\lib\site-packages\sqlalchemy\pool\impl.py", line 140, in _do_get
    self._dec_overflow()
  File "D:\ProgramData\Anaconda3\envs\py36\lib\site-packages\sqlalchemy\util\langhelpers.py", line 70, in __exit__
    with_traceback=exc_tb,
  File "D:\ProgramData\Anaconda3\envs\py36\lib\site-packages\sqlalchemy\util\compat.py", line 182, in raise_
    raise exception
  File "D:\ProgramData\Anaconda3\envs\py36\lib\site-packages\sqlalchemy\pool\impl.py", line 137, in _do_get
    return self._create_connection()
  File "D:\ProgramData\Anaconda3\envs\py36\lib\site-packages\sqlalchemy\pool\base.py", line 309, in _create_connection
    return _ConnectionRecord(self)
  File "D:\ProgramData\Anaconda3\envs\py36\lib\site-packages\sqlalchemy\pool\base.py", line 440, in __init__
    self.__connect(first_connect_check=True)
  File "D:\ProgramData\Anaconda3\envs\py36\lib\site-packages\sqlalchemy\pool\base.py", line 661, in __connect
    pool.logger.debug("Error on connect(): %s", e)
  File "D:\ProgramData\Anaconda3\envs\py36\lib\site-packages\sqlalchemy\util\langhelpers.py", line 70, in __exit__
    with_traceback=exc_tb,
  File "D:\ProgramData\Anaconda3\envs\py36\lib\site-packages\sqlalchemy\util\compat.py", line 182, in raise_
    raise exception
  File "D:\ProgramData\Anaconda3\envs\py36\lib\site-packages\sqlalchemy\pool\base.py", line 656, in __connect
    connection = pool._invoke_creator(self)
  File "D:\ProgramData\Anaconda3\envs\py36\lib\site-packages\sqlalchemy\engine\strategies.py", line 114, in connect
    return dialect.connect(*cargs, **cparams)
  File "D:\ProgramData\Anaconda3\envs\py36\lib\site-packages\sqlalchemy\engine\default.py", line 508, in connect
    return self.dbapi.connect(*cargs, **cparams)
  File "D:\ProgramData\Anaconda3\envs\py36\lib\site-packages\pymysql\connections.py", line 353, in __init__
    self.connect()
  File "D:\ProgramData\Anaconda3\envs\py36\lib\site-packages\pymysql\connections.py", line 664, in connect
    raise exc
sqlalchemy.exc.OperationalError: (pymysql.err.OperationalError) (2003, "Can't connect to MySQL server on '192.168.8.58' (timed out)")
(Background on this error at: http://sqlalche.me/e/13/e3q8)
ERROR:tornado.access:500 GET /login?username=liubin&password=123456 (127.0.0.1) 10015.32ms
ERROR:tornado.application:Uncaught exception GET /login?username=liubin&password=123456 (127.0.0.1)
HTTPServerRequest(protocol='http', host='localhost:8080', method='GET', uri='/login?username=liubin&password=123456', version='HTTP/1.1', remote_ip='127.0.0.1')
Traceback (most recent call last):
  File "D:\ProgramData\Anaconda3\envs\py36\lib\site-packages\pymysql\connections.py", line 614, in connect
    (self.host, self.port), self.connect_timeout, **kwargs
  File "D:\ProgramData\Anaconda3\envs\py36\lib\socket.py", line 724, in create_connection
    raise err
  File "D:\ProgramData\Anaconda3\envs\py36\lib\socket.py", line 713, in create_connection
    sock.connect(sa)
socket.timeout: timed out

During handling of the above exception, another exception occurred:

Traceback (most recent call last):
  File "D:\ProgramData\Anaconda3\envs\py36\lib\site-packages\sqlalchemy\engine\base.py", line 2336, in _wrap_pool_connect
    return fn()
  File "D:\ProgramData\Anaconda3\envs\py36\lib\site-packages\sqlalchemy\pool\base.py", line 364, in connect
    return _ConnectionFairy._checkout(self)
  File "D:\ProgramData\Anaconda3\envs\py36\lib\site-packages\sqlalchemy\pool\base.py", line 778, in _checkout
    fairy = _ConnectionRecord.checkout(pool)
  File "D:\ProgramData\Anaconda3\envs\py36\lib\site-packages\sqlalchemy\pool\base.py", line 495, in checkout
    rec = pool._do_get()
  File "D:\ProgramData\Anaconda3\envs\py36\lib\site-packages\sqlalchemy\pool\impl.py", line 140, in _do_get
    self._dec_overflow()
  File "D:\ProgramData\Anaconda3\envs\py36\lib\site-packages\sqlalchemy\util\langhelpers.py", line 70, in __exit__
    with_traceback=exc_tb,
  File "D:\ProgramData\Anaconda3\envs\py36\lib\site-packages\sqlalchemy\util\compat.py", line 182, in raise_
    raise exception
  File "D:\ProgramData\Anaconda3\envs\py36\lib\site-packages\sqlalchemy\pool\impl.py", line 137, in _do_get
    return self._create_connection()
  File "D:\ProgramData\Anaconda3\envs\py36\lib\site-packages\sqlalchemy\pool\base.py", line 309, in _create_connection
    return _ConnectionRecord(self)
  File "D:\ProgramData\Anaconda3\envs\py36\lib\site-packages\sqlalchemy\pool\base.py", line 440, in __init__
    self.__connect(first_connect_check=True)
  File "D:\ProgramData\Anaconda3\envs\py36\lib\site-packages\sqlalchemy\pool\base.py", line 661, in __connect
    pool.logger.debug("Error on connect(): %s", e)
  File "D:\ProgramData\Anaconda3\envs\py36\lib\site-packages\sqlalchemy\util\langhelpers.py", line 70, in __exit__
    with_traceback=exc_tb,
  File "D:\ProgramData\Anaconda3\envs\py36\lib\site-packages\sqlalchemy\util\compat.py", line 182, in raise_
    raise exception
  File "D:\ProgramData\Anaconda3\envs\py36\lib\site-packages\sqlalchemy\pool\base.py", line 656, in __connect
    connection = pool._invoke_creator(self)
  File "D:\ProgramData\Anaconda3\envs\py36\lib\site-packages\sqlalchemy\engine\strategies.py", line 114, in connect
    return dialect.connect(*cargs, **cparams)
  File "D:\ProgramData\Anaconda3\envs\py36\lib\site-packages\sqlalchemy\engine\default.py", line 508, in connect
    return self.dbapi.connect(*cargs, **cparams)
  File "D:\ProgramData\Anaconda3\envs\py36\lib\site-packages\pymysql\connections.py", line 353, in __init__
    self.connect()
  File "D:\ProgramData\Anaconda3\envs\py36\lib\site-packages\pymysql\connections.py", line 664, in connect
    raise exc
pymysql.err.OperationalError: (2003, "Can't connect to MySQL server on '192.168.8.58' (timed out)")

The above exception was the direct cause of the following exception:

Traceback (most recent call last):
  File "D:\ProgramData\Anaconda3\envs\py36\lib\site-packages\tornado\web.py", line 1590, in _execute
    result = method(*self.path_args, **self.path_kwargs)
  File "C:\Users\Ð¡Æß\Desktop\MyTornado\handlers\public\loginhandle.py", line 21, in get
    user.open()
  File "C:\Users\Ð¡Æß\Desktop\MyTornado\handlers\public\sql_orm.py", line 38, in open
    Base.metadata.create_all(engine)
  File "D:\ProgramData\Anaconda3\envs\py36\lib\site-packages\sqlalchemy\sql\schema.py", line 4664, in create_all
    ddl.SchemaGenerator, self, checkfirst=checkfirst, tables=tables
  File "D:\ProgramData\Anaconda3\envs\py36\lib\site-packages\sqlalchemy\engine\base.py", line 2094, in _run_visitor
    with self._optional_conn_ctx_manager(connection) as conn:
  File "D:\ProgramData\Anaconda3\envs\py36\lib\contextlib.py", line 81, in __enter__
    return next(self.gen)
  File "D:\ProgramData\Anaconda3\envs\py36\lib\site-packages\sqlalchemy\engine\base.py", line 2086, in _optional_conn_ctx_manager
    with self._contextual_connect() as conn:
  File "D:\ProgramData\Anaconda3\envs\py36\lib\site-packages\sqlalchemy\engine\base.py", line 2302, in _contextual_connect
    self._wrap_pool_connect(self.pool.connect, None),
  File "D:\ProgramData\Anaconda3\envs\py36\lib\site-packages\sqlalchemy\engine\base.py", line 2340, in _wrap_pool_connect
    e, dialect, self
  File "D:\ProgramData\Anaconda3\envs\py36\lib\site-packages\sqlalchemy\engine\base.py", line 1584, in _handle_dbapi_exception_noconnection
    sqlalchemy_exception, with_traceback=exc_info[2], from_=e
  File "D:\ProgramData\Anaconda3\envs\py36\lib\site-packages\sqlalchemy\util\compat.py", line 182, in raise_
    raise exception
  File "D:\ProgramData\Anaconda3\envs\py36\lib\site-packages\sqlalchemy\engine\base.py", line 2336, in _wrap_pool_connect
    return fn()
  File "D:\ProgramData\Anaconda3\envs\py36\lib\site-packages\sqlalchemy\pool\base.py", line 364, in connect
    return _ConnectionFairy._checkout(self)
  File "D:\ProgramData\Anaconda3\envs\py36\lib\site-packages\sqlalchemy\pool\base.py", line 778, in _checkout
    fairy = _ConnectionRecord.checkout(pool)
  File "D:\ProgramData\Anaconda3\envs\py36\lib\site-packages\sqlalchemy\pool\base.py", line 495, in checkout
    rec = pool._do_get()
  File "D:\ProgramData\Anaconda3\envs\py36\lib\site-packages\sqlalchemy\pool\impl.py", line 140, in _do_get
    self._dec_overflow()
  File "D:\ProgramData\Anaconda3\envs\py36\lib\site-packages\sqlalchemy\util\langhelpers.py", line 70, in __exit__
    with_traceback=exc_tb,
  File "D:\ProgramData\Anaconda3\envs\py36\lib\site-packages\sqlalchemy\util\compat.py", line 182, in raise_
    raise exception
  File "D:\ProgramData\Anaconda3\envs\py36\lib\site-packages\sqlalchemy\pool\impl.py", line 137, in _do_get
    return self._create_connection()
  File "D:\ProgramData\Anaconda3\envs\py36\lib\site-packages\sqlalchemy\pool\base.py", line 309, in _create_connection
    return _ConnectionRecord(self)
  File "D:\ProgramData\Anaconda3\envs\py36\lib\site-packages\sqlalchemy\pool\base.py", line 440, in __init__
    self.__connect(first_connect_check=True)
  File "D:\ProgramData\Anaconda3\envs\py36\lib\site-packages\sqlalchemy\pool\base.py", line 661, in __connect
    pool.logger.debug("Error on connect(): %s", e)
  File "D:\ProgramData\Anaconda3\envs\py36\lib\site-packages\sqlalchemy\util\langhelpers.py", line 70, in __exit__
    with_traceback=exc_tb,
  File "D:\ProgramData\Anaconda3\envs\py36\lib\site-packages\sqlalchemy\util\compat.py", line 182, in raise_
    raise exception
  File "D:\ProgramData\Anaconda3\envs\py36\lib\site-packages\sqlalchemy\pool\base.py", line 656, in __connect
    connection = pool._invoke_creator(self)
  File "D:\ProgramData\Anaconda3\envs\py36\lib\site-packages\sqlalchemy\engine\strategies.py", line 114, in connect
    return dialect.connect(*cargs, **cparams)
  File "D:\ProgramData\Anaconda3\envs\py36\lib\site-packages\sqlalchemy\engine\default.py", line 508, in connect
    return self.dbapi.connect(*cargs, **cparams)
  File "D:\ProgramData\Anaconda3\envs\py36\lib\site-packages\pymysql\connections.py", line 353, in __init__
    self.connect()
  File "D:\ProgramData\Anaconda3\envs\py36\lib\site-packages\pymysql\connections.py", line 664, in connect
    raise exc
sqlalchemy.exc.OperationalError: (pymysql.err.OperationalError) (2003, "Can't connect to MySQL server on '192.168.8.58' (timed out)")
(Background on this error at: http://sqlalche.me/e/13/e3q8)
ERROR:tornado.access:500 GET /login?username=liubin&password=123456 (127.0.0.1) 10109.04ms
ERROR:tornado.application:Uncaught exception GET /login?username=liubin&password=123456 (127.0.0.1)
HTTPServerRequest(protocol='http', host='localhost:8080', method='GET', uri='/login?username=liubin&password=123456', version='HTTP/1.1', remote_ip='127.0.0.1')
Traceback (most recent call last):
  File "D:\ProgramData\Anaconda3\envs\py36\lib\site-packages\pymysql\connections.py", line 614, in connect
    (self.host, self.port), self.connect_timeout, **kwargs
  File "D:\ProgramData\Anaconda3\envs\py36\lib\socket.py", line 724, in create_connection
    raise err
  File "D:\ProgramData\Anaconda3\envs\py36\lib\socket.py", line 713, in create_connection
    sock.connect(sa)
socket.timeout: timed out

During handling of the above exception, another exception occurred:

Traceback (most recent call last):
  File "D:\ProgramData\Anaconda3\envs\py36\lib\site-packages\sqlalchemy\engine\base.py", line 2336, in _wrap_pool_connect
    return fn()
  File "D:\ProgramData\Anaconda3\envs\py36\lib\site-packages\sqlalchemy\pool\base.py", line 364, in connect
    return _ConnectionFairy._checkout(self)
  File "D:\ProgramData\Anaconda3\envs\py36\lib\site-packages\sqlalchemy\pool\base.py", line 778, in _checkout
    fairy = _ConnectionRecord.checkout(pool)
  File "D:\ProgramData\Anaconda3\envs\py36\lib\site-packages\sqlalchemy\pool\base.py", line 495, in checkout
    rec = pool._do_get()
  File "D:\ProgramData\Anaconda3\envs\py36\lib\site-packages\sqlalchemy\pool\impl.py", line 140, in _do_get
    self._dec_overflow()
  File "D:\ProgramData\Anaconda3\envs\py36\lib\site-packages\sqlalchemy\util\langhelpers.py", line 70, in __exit__
    with_traceback=exc_tb,
  File "D:\ProgramData\Anaconda3\envs\py36\lib\site-packages\sqlalchemy\util\compat.py", line 182, in raise_
    raise exception
  File "D:\ProgramData\Anaconda3\envs\py36\lib\site-packages\sqlalchemy\pool\impl.py", line 137, in _do_get
    return self._create_connection()
  File "D:\ProgramData\Anaconda3\envs\py36\lib\site-packages\sqlalchemy\pool\base.py", line 309, in _create_connection
    return _ConnectionRecord(self)
  File "D:\ProgramData\Anaconda3\envs\py36\lib\site-packages\sqlalchemy\pool\base.py", line 440, in __init__
    self.__connect(first_connect_check=True)
  File "D:\ProgramData\Anaconda3\envs\py36\lib\site-packages\sqlalchemy\pool\base.py", line 661, in __connect
    pool.logger.debug("Error on connect(): %s", e)
  File "D:\ProgramData\Anaconda3\envs\py36\lib\site-packages\sqlalchemy\util\langhelpers.py", line 70, in __exit__
    with_traceback=exc_tb,
  File "D:\ProgramData\Anaconda3\envs\py36\lib\site-packages\sqlalchemy\util\compat.py", line 182, in raise_
    raise exception
  File "D:\ProgramData\Anaconda3\envs\py36\lib\site-packages\sqlalchemy\pool\base.py", line 656, in __connect
    connection = pool._invoke_creator(self)
  File "D:\ProgramData\Anaconda3\envs\py36\lib\site-packages\sqlalchemy\engine\strategies.py", line 114, in connect
    return dialect.connect(*cargs, **cparams)
  File "D:\ProgramData\Anaconda3\envs\py36\lib\site-packages\sqlalchemy\engine\default.py", line 508, in connect
    return self.dbapi.connect(*cargs, **cparams)
  File "D:\ProgramData\Anaconda3\envs\py36\lib\site-packages\pymysql\connections.py", line 353, in __init__
    self.connect()
  File "D:\ProgramData\Anaconda3\envs\py36\lib\site-packages\pymysql\connections.py", line 664, in connect
    raise exc
pymysql.err.OperationalError: (2003, "Can't connect to MySQL server on '192.168.8.58' (timed out)")

The above exception was the direct cause of the following exception:

Traceback (most recent call last):
  File "D:\ProgramData\Anaconda3\envs\py36\lib\site-packages\tornado\web.py", line 1590, in _execute
    result = method(*self.path_args, **self.path_kwargs)
  File "C:\Users\Ð¡Æß\Desktop\MyTornado\handlers\public\loginhandle.py", line 21, in get
    user.open()
  File "C:\Users\Ð¡Æß\Desktop\MyTornado\handlers\public\sql_orm.py", line 38, in open
    Base.metadata.create_all(engine)
  File "D:\ProgramData\Anaconda3\envs\py36\lib\site-packages\sqlalchemy\sql\schema.py", line 4664, in create_all
    ddl.SchemaGenerator, self, checkfirst=checkfirst, tables=tables
  File "D:\ProgramData\Anaconda3\envs\py36\lib\site-packages\sqlalchemy\engine\base.py", line 2094, in _run_visitor
    with self._optional_conn_ctx_manager(connection) as conn:
  File "D:\ProgramData\Anaconda3\envs\py36\lib\contextlib.py", line 81, in __enter__
    return next(self.gen)
  File "D:\ProgramData\Anaconda3\envs\py36\lib\site-packages\sqlalchemy\engine\base.py", line 2086, in _optional_conn_ctx_manager
    with self._contextual_connect() as conn:
  File "D:\ProgramData\Anaconda3\envs\py36\lib\site-packages\sqlalchemy\engine\base.py", line 2302, in _contextual_connect
    self._wrap_pool_connect(self.pool.connect, None),
  File "D:\ProgramData\Anaconda3\envs\py36\lib\site-packages\sqlalchemy\engine\base.py", line 2340, in _wrap_pool_connect
    e, dialect, self
  File "D:\ProgramData\Anaconda3\envs\py36\lib\site-packages\sqlalchemy\engine\base.py", line 1584, in _handle_dbapi_exception_noconnection
    sqlalchemy_exception, with_traceback=exc_info[2], from_=e
  File "D:\ProgramData\Anaconda3\envs\py36\lib\site-packages\sqlalchemy\util\compat.py", line 182, in raise_
    raise exception
  File "D:\ProgramData\Anaconda3\envs\py36\lib\site-packages\sqlalchemy\engine\base.py", line 2336, in _wrap_pool_connect
    return fn()
  File "D:\ProgramData\Anaconda3\envs\py36\lib\site-packages\sqlalchemy\pool\base.py", line 364, in connect
    return _ConnectionFairy._checkout(self)
  File "D:\ProgramData\Anaconda3\envs\py36\lib\site-packages\sqlalchemy\pool\base.py", line 778, in _checkout
    fairy = _ConnectionRecord.checkout(pool)
  File "D:\ProgramData\Anaconda3\envs\py36\lib\site-packages\sqlalchemy\pool\base.py", line 495, in checkout
    rec = pool._do_get()
  File "D:\ProgramData\Anaconda3\envs\py36\lib\site-packages\sqlalchemy\pool\impl.py", line 140, in _do_get
    self._dec_overflow()
  File "D:\ProgramData\Anaconda3\envs\py36\lib\site-packages\sqlalchemy\util\langhelpers.py", line 70, in __exit__
    with_traceback=exc_tb,
  File "D:\ProgramData\Anaconda3\envs\py36\lib\site-packages\sqlalchemy\util\compat.py", line 182, in raise_
    raise exception
  File "D:\ProgramData\Anaconda3\envs\py36\lib\site-packages\sqlalchemy\pool\impl.py", line 137, in _do_get
    return self._create_connection()
  File "D:\ProgramData\Anaconda3\envs\py36\lib\site-packages\sqlalchemy\pool\base.py", line 309, in _create_connection
    return _ConnectionRecord(self)
  File "D:\ProgramData\Anaconda3\envs\py36\lib\site-packages\sqlalchemy\pool\base.py", line 440, in __init__
    self.__connect(first_connect_check=True)
  File "D:\ProgramData\Anaconda3\envs\py36\lib\site-packages\sqlalchemy\pool\base.py", line 661, in __connect
    pool.logger.debug("Error on connect(): %s", e)
  File "D:\ProgramData\Anaconda3\envs\py36\lib\site-packages\sqlalchemy\util\langhelpers.py", line 70, in __exit__
    with_traceback=exc_tb,
  File "D:\ProgramData\Anaconda3\envs\py36\lib\site-packages\sqlalchemy\util\compat.py", line 182, in raise_
    raise exception
  File "D:\ProgramData\Anaconda3\envs\py36\lib\site-packages\sqlalchemy\pool\base.py", line 656, in __connect
    connection = pool._invoke_creator(self)
  File "D:\ProgramData\Anaconda3\envs\py36\lib\site-packages\sqlalchemy\engine\strategies.py", line 114, in connect
    return dialect.connect(*cargs, **cparams)
  File "D:\ProgramData\Anaconda3\envs\py36\lib\site-packages\sqlalchemy\engine\default.py", line 508, in connect
    return self.dbapi.connect(*cargs, **cparams)
  File "D:\ProgramData\Anaconda3\envs\py36\lib\site-packages\pymysql\connections.py", line 353, in __init__
    self.connect()
  File "D:\ProgramData\Anaconda3\envs\py36\lib\site-packages\pymysql\connections.py", line 664, in connect
    raise exc
sqlalchemy.exc.OperationalError: (pymysql.err.OperationalError) (2003, "Can't connect to MySQL server on '192.168.8.58' (timed out)")
(Background on this error at: http://sqlalche.me/e/13/e3q8)
ERROR:tornado.access:500 GET /login?username=liubin&password=123456 (127.0.0.1) 10014.37ms
ERROR:tornado.application:Uncaught exception GET /login?username=liubin&password=123456 (127.0.0.1)
HTTPServerRequest(protocol='http', host='localhost:8080', method='GET', uri='/login?username=liubin&password=123456', version='HTTP/1.1', remote_ip='127.0.0.1')
Traceback (most recent call last):
  File "D:\ProgramData\Anaconda3\envs\py36\lib\site-packages\pymysql\connections.py", line 614, in connect
    (self.host, self.port), self.connect_timeout, **kwargs
  File "D:\ProgramData\Anaconda3\envs\py36\lib\socket.py", line 724, in create_connection
    raise err
  File "D:\ProgramData\Anaconda3\envs\py36\lib\socket.py", line 713, in create_connection
    sock.connect(sa)
socket.timeout: timed out

During handling of the above exception, another exception occurred:

Traceback (most recent call last):
  File "D:\ProgramData\Anaconda3\envs\py36\lib\site-packages\sqlalchemy\engine\base.py", line 2336, in _wrap_pool_connect
    return fn()
  File "D:\ProgramData\Anaconda3\envs\py36\lib\site-packages\sqlalchemy\pool\base.py", line 364, in connect
    return _ConnectionFairy._checkout(self)
  File "D:\ProgramData\Anaconda3\envs\py36\lib\site-packages\sqlalchemy\pool\base.py", line 778, in _checkout
    fairy = _ConnectionRecord.checkout(pool)
  File "D:\ProgramData\Anaconda3\envs\py36\lib\site-packages\sqlalchemy\pool\base.py", line 495, in checkout
    rec = pool._do_get()
  File "D:\ProgramData\Anaconda3\envs\py36\lib\site-packages\sqlalchemy\pool\impl.py", line 140, in _do_get
    self._dec_overflow()
  File "D:\ProgramData\Anaconda3\envs\py36\lib\site-packages\sqlalchemy\util\langhelpers.py", line 70, in __exit__
    with_traceback=exc_tb,
  File "D:\ProgramData\Anaconda3\envs\py36\lib\site-packages\sqlalchemy\util\compat.py", line 182, in raise_
    raise exception
  File "D:\ProgramData\Anaconda3\envs\py36\lib\site-packages\sqlalchemy\pool\impl.py", line 137, in _do_get
    return self._create_connection()
  File "D:\ProgramData\Anaconda3\envs\py36\lib\site-packages\sqlalchemy\pool\base.py", line 309, in _create_connection
    return _ConnectionRecord(self)
  File "D:\ProgramData\Anaconda3\envs\py36\lib\site-packages\sqlalchemy\pool\base.py", line 440, in __init__
    self.__connect(first_connect_check=True)
  File "D:\ProgramData\Anaconda3\envs\py36\lib\site-packages\sqlalchemy\pool\base.py", line 661, in __connect
    pool.logger.debug("Error on connect(): %s", e)
  File "D:\ProgramData\Anaconda3\envs\py36\lib\site-packages\sqlalchemy\util\langhelpers.py", line 70, in __exit__
    with_traceback=exc_tb,
  File "D:\ProgramData\Anaconda3\envs\py36\lib\site-packages\sqlalchemy\util\compat.py", line 182, in raise_
    raise exception
  File "D:\ProgramData\Anaconda3\envs\py36\lib\site-packages\sqlalchemy\pool\base.py", line 656, in __connect
    connection = pool._invoke_creator(self)
  File "D:\ProgramData\Anaconda3\envs\py36\lib\site-packages\sqlalchemy\engine\strategies.py", line 114, in connect
    return dialect.connect(*cargs, **cparams)
  File "D:\ProgramData\Anaconda3\envs\py36\lib\site-packages\sqlalchemy\engine\default.py", line 508, in connect
    return self.dbapi.connect(*cargs, **cparams)
  File "D:\ProgramData\Anaconda3\envs\py36\lib\site-packages\pymysql\connections.py", line 353, in __init__
    self.connect()
  File "D:\ProgramData\Anaconda3\envs\py36\lib\site-packages\pymysql\connections.py", line 664, in connect
    raise exc
pymysql.err.OperationalError: (2003, "Can't connect to MySQL server on '192.168.8.58' (timed out)")

The above exception was the direct cause of the following exception:

Traceback (most recent call last):
  File "D:\ProgramData\Anaconda3\envs\py36\lib\site-packages\tornado\web.py", line 1590, in _execute
    result = method(*self.path_args, **self.path_kwargs)
  File "C:\Users\Ð¡Æß\Desktop\MyTornado\handlers\public\loginhandle.py", line 21, in get
    user.open()
  File "C:\Users\Ð¡Æß\Desktop\MyTornado\handlers\public\sql_orm.py", line 38, in open
    Base.metadata.create_all(engine)
  File "D:\ProgramData\Anaconda3\envs\py36\lib\site-packages\sqlalchemy\sql\schema.py", line 4664, in create_all
    ddl.SchemaGenerator, self, checkfirst=checkfirst, tables=tables
  File "D:\ProgramData\Anaconda3\envs\py36\lib\site-packages\sqlalchemy\engine\base.py", line 2094, in _run_visitor
    with self._optional_conn_ctx_manager(connection) as conn:
  File "D:\ProgramData\Anaconda3\envs\py36\lib\contextlib.py", line 81, in __enter__
    return next(self.gen)
  File "D:\ProgramData\Anaconda3\envs\py36\lib\site-packages\sqlalchemy\engine\base.py", line 2086, in _optional_conn_ctx_manager
    with self._contextual_connect() as conn:
  File "D:\ProgramData\Anaconda3\envs\py36\lib\site-packages\sqlalchemy\engine\base.py", line 2302, in _contextual_connect
    self._wrap_pool_connect(self.pool.connect, None),
  File "D:\ProgramData\Anaconda3\envs\py36\lib\site-packages\sqlalchemy\engine\base.py", line 2340, in _wrap_pool_connect
    e, dialect, self
  File "D:\ProgramData\Anaconda3\envs\py36\lib\site-packages\sqlalchemy\engine\base.py", line 1584, in _handle_dbapi_exception_noconnection
    sqlalchemy_exception, with_traceback=exc_info[2], from_=e
  File "D:\ProgramData\Anaconda3\envs\py36\lib\site-packages\sqlalchemy\util\compat.py", line 182, in raise_
    raise exception
  File "D:\ProgramData\Anaconda3\envs\py36\lib\site-packages\sqlalchemy\engine\base.py", line 2336, in _wrap_pool_connect
    return fn()
  File "D:\ProgramData\Anaconda3\envs\py36\lib\site-packages\sqlalchemy\pool\base.py", line 364, in connect
    return _ConnectionFairy._checkout(self)
  File "D:\ProgramData\Anaconda3\envs\py36\lib\site-packages\sqlalchemy\pool\base.py", line 778, in _checkout
    fairy = _ConnectionRecord.checkout(pool)
  File "D:\ProgramData\Anaconda3\envs\py36\lib\site-packages\sqlalchemy\pool\base.py", line 495, in checkout
    rec = pool._do_get()
  File "D:\ProgramData\Anaconda3\envs\py36\lib\site-packages\sqlalchemy\pool\impl.py", line 140, in _do_get
    self._dec_overflow()
  File "D:\ProgramData\Anaconda3\envs\py36\lib\site-packages\sqlalchemy\util\langhelpers.py", line 70, in __exit__
    with_traceback=exc_tb,
  File "D:\ProgramData\Anaconda3\envs\py36\lib\site-packages\sqlalchemy\util\compat.py", line 182, in raise_
    raise exception
  File "D:\ProgramData\Anaconda3\envs\py36\lib\site-packages\sqlalchemy\pool\impl.py", line 137, in _do_get
    return self._create_connection()
  File "D:\ProgramData\Anaconda3\envs\py36\lib\site-packages\sqlalchemy\pool\base.py", line 309, in _create_connection
    return _ConnectionRecord(self)
  File "D:\ProgramData\Anaconda3\envs\py36\lib\site-packages\sqlalchemy\pool\base.py", line 440, in __init__
    self.__connect(first_connect_check=True)
  File "D:\ProgramData\Anaconda3\envs\py36\lib\site-packages\sqlalchemy\pool\base.py", line 661, in __connect
    pool.logger.debug("Error on connect(): %s", e)
  File "D:\ProgramData\Anaconda3\envs\py36\lib\site-packages\sqlalchemy\util\langhelpers.py", line 70, in __exit__
    with_traceback=exc_tb,
  File "D:\ProgramData\Anaconda3\envs\py36\lib\site-packages\sqlalchemy\util\compat.py", line 182, in raise_
    raise exception
  File "D:\ProgramData\Anaconda3\envs\py36\lib\site-packages\sqlalchemy\pool\base.py", line 656, in __connect
    connection = pool._invoke_creator(self)
  File "D:\ProgramData\Anaconda3\envs\py36\lib\site-packages\sqlalchemy\engine\strategies.py", line 114, in connect
    return dialect.connect(*cargs, **cparams)
  File "D:\ProgramData\Anaconda3\envs\py36\lib\site-packages\sqlalchemy\engine\default.py", line 508, in connect
    return self.dbapi.connect(*cargs, **cparams)
  File "D:\ProgramData\Anaconda3\envs\py36\lib\site-packages\pymysql\connections.py", line 353, in __init__
    self.connect()
  File "D:\ProgramData\Anaconda3\envs\py36\lib\site-packages\pymysql\connections.py", line 664, in connect
    raise exc
sqlalchemy.exc.OperationalError: (pymysql.err.OperationalError) (2003, "Can't connect to MySQL server on '192.168.8.58' (timed out)")
(Background on this error at: http://sqlalche.me/e/13/e3q8)
ERROR:tornado.access:500 GET /login?username=liubin&password=123456 (127.0.0.1) 10114.76ms
ERROR:tornado.application:Uncaught exception GET /login?username=liubin&password=123456 (127.0.0.1)
HTTPServerRequest(protocol='http', host='localhost:8080', method='GET', uri='/login?username=liubin&password=123456', version='HTTP/1.1', remote_ip='127.0.0.1')
Traceback (most recent call last):
  File "D:\ProgramData\Anaconda3\envs\py36\lib\site-packages\pymysql\connections.py", line 614, in connect
    (self.host, self.port), self.connect_timeout, **kwargs
  File "D:\ProgramData\Anaconda3\envs\py36\lib\socket.py", line 724, in create_connection
    raise err
  File "D:\ProgramData\Anaconda3\envs\py36\lib\socket.py", line 713, in create_connection
    sock.connect(sa)
socket.timeout: timed out

During handling of the above exception, another exception occurred:

Traceback (most recent call last):
  File "D:\ProgramData\Anaconda3\envs\py36\lib\site-packages\sqlalchemy\engine\base.py", line 2336, in _wrap_pool_connect
    return fn()
  File "D:\ProgramData\Anaconda3\envs\py36\lib\site-packages\sqlalchemy\pool\base.py", line 364, in connect
    return _ConnectionFairy._checkout(self)
  File "D:\ProgramData\Anaconda3\envs\py36\lib\site-packages\sqlalchemy\pool\base.py", line 778, in _checkout
    fairy = _ConnectionRecord.checkout(pool)
  File "D:\ProgramData\Anaconda3\envs\py36\lib\site-packages\sqlalchemy\pool\base.py", line 495, in checkout
    rec = pool._do_get()
  File "D:\ProgramData\Anaconda3\envs\py36\lib\site-packages\sqlalchemy\pool\impl.py", line 140, in _do_get
    self._dec_overflow()
  File "D:\ProgramData\Anaconda3\envs\py36\lib\site-packages\sqlalchemy\util\langhelpers.py", line 70, in __exit__
    with_traceback=exc_tb,
  File "D:\ProgramData\Anaconda3\envs\py36\lib\site-packages\sqlalchemy\util\compat.py", line 182, in raise_
    raise exception
  File "D:\ProgramData\Anaconda3\envs\py36\lib\site-packages\sqlalchemy\pool\impl.py", line 137, in _do_get
    return self._create_connection()
  File "D:\ProgramData\Anaconda3\envs\py36\lib\site-packages\sqlalchemy\pool\base.py", line 309, in _create_connection
    return _ConnectionRecord(self)
  File "D:\ProgramData\Anaconda3\envs\py36\lib\site-packages\sqlalchemy\pool\base.py", line 440, in __init__
    self.__connect(first_connect_check=True)
  File "D:\ProgramData\Anaconda3\envs\py36\lib\site-packages\sqlalchemy\pool\base.py", line 661, in __connect
    pool.logger.debug("Error on connect(): %s", e)
  File "D:\ProgramData\Anaconda3\envs\py36\lib\site-packages\sqlalchemy\util\langhelpers.py", line 70, in __exit__
    with_traceback=exc_tb,
  File "D:\ProgramData\Anaconda3\envs\py36\lib\site-packages\sqlalchemy\util\compat.py", line 182, in raise_
    raise exception
  File "D:\ProgramData\Anaconda3\envs\py36\lib\site-packages\sqlalchemy\pool\base.py", line 656, in __connect
    connection = pool._invoke_creator(self)
  File "D:\ProgramData\Anaconda3\envs\py36\lib\site-packages\sqlalchemy\engine\strategies.py", line 114, in connect
    return dialect.connect(*cargs, **cparams)
  File "D:\ProgramData\Anaconda3\envs\py36\lib\site-packages\sqlalchemy\engine\default.py", line 508, in connect
    return self.dbapi.connect(*cargs, **cparams)
  File "D:\ProgramData\Anaconda3\envs\py36\lib\site-packages\pymysql\connections.py", line 353, in __init__
    self.connect()
  File "D:\ProgramData\Anaconda3\envs\py36\lib\site-packages\pymysql\connections.py", line 664, in connect
    raise exc
pymysql.err.OperationalError: (2003, "Can't connect to MySQL server on '192.168.8.58' (timed out)")

The above exception was the direct cause of the following exception:

Traceback (most recent call last):
  File "D:\ProgramData\Anaconda3\envs\py36\lib\site-packages\tornado\web.py", line 1590, in _execute
    result = method(*self.path_args, **self.path_kwargs)
  File "C:\Users\Ð¡Æß\Desktop\MyTornado\handlers\public\loginhandle.py", line 21, in get
    user.open()
  File "C:\Users\Ð¡Æß\Desktop\MyTornado\handlers\public\sql_orm.py", line 38, in open
    Base.metadata.create_all(engine)
  File "D:\ProgramData\Anaconda3\envs\py36\lib\site-packages\sqlalchemy\sql\schema.py", line 4664, in create_all
    ddl.SchemaGenerator, self, checkfirst=checkfirst, tables=tables
  File "D:\ProgramData\Anaconda3\envs\py36\lib\site-packages\sqlalchemy\engine\base.py", line 2094, in _run_visitor
    with self._optional_conn_ctx_manager(connection) as conn:
  File "D:\ProgramData\Anaconda3\envs\py36\lib\contextlib.py", line 81, in __enter__
    return next(self.gen)
  File "D:\ProgramData\Anaconda3\envs\py36\lib\site-packages\sqlalchemy\engine\base.py", line 2086, in _optional_conn_ctx_manager
    with self._contextual_connect() as conn:
  File "D:\ProgramData\Anaconda3\envs\py36\lib\site-packages\sqlalchemy\engine\base.py", line 2302, in _contextual_connect
    self._wrap_pool_connect(self.pool.connect, None),
  File "D:\ProgramData\Anaconda3\envs\py36\lib\site-packages\sqlalchemy\engine\base.py", line 2340, in _wrap_pool_connect
    e, dialect, self
  File "D:\ProgramData\Anaconda3\envs\py36\lib\site-packages\sqlalchemy\engine\base.py", line 1584, in _handle_dbapi_exception_noconnection
    sqlalchemy_exception, with_traceback=exc_info[2], from_=e
  File "D:\ProgramData\Anaconda3\envs\py36\lib\site-packages\sqlalchemy\util\compat.py", line 182, in raise_
    raise exception
  File "D:\ProgramData\Anaconda3\envs\py36\lib\site-packages\sqlalchemy\engine\base.py", line 2336, in _wrap_pool_connect
    return fn()
  File "D:\ProgramData\Anaconda3\envs\py36\lib\site-packages\sqlalchemy\pool\base.py", line 364, in connect
    return _ConnectionFairy._checkout(self)
  File "D:\ProgramData\Anaconda3\envs\py36\lib\site-packages\sqlalchemy\pool\base.py", line 778, in _checkout
    fairy = _ConnectionRecord.checkout(pool)
  File "D:\ProgramData\Anaconda3\envs\py36\lib\site-packages\sqlalchemy\pool\base.py", line 495, in checkout
    rec = pool._do_get()
  File "D:\ProgramData\Anaconda3\envs\py36\lib\site-packages\sqlalchemy\pool\impl.py", line 140, in _do_get
    self._dec_overflow()
  File "D:\ProgramData\Anaconda3\envs\py36\lib\site-packages\sqlalchemy\util\langhelpers.py", line 70, in __exit__
    with_traceback=exc_tb,
  File "D:\ProgramData\Anaconda3\envs\py36\lib\site-packages\sqlalchemy\util\compat.py", line 182, in raise_
    raise exception
  File "D:\ProgramData\Anaconda3\envs\py36\lib\site-packages\sqlalchemy\pool\impl.py", line 137, in _do_get
    return self._create_connection()
  File "D:\ProgramData\Anaconda3\envs\py36\lib\site-packages\sqlalchemy\pool\base.py", line 309, in _create_connection
    return _ConnectionRecord(self)
  File "D:\ProgramData\Anaconda3\envs\py36\lib\site-packages\sqlalchemy\pool\base.py", line 440, in __init__
    self.__connect(first_connect_check=True)
  File "D:\ProgramData\Anaconda3\envs\py36\lib\site-packages\sqlalchemy\pool\base.py", line 661, in __connect
    pool.logger.debug("Error on connect(): %s", e)
  File "D:\ProgramData\Anaconda3\envs\py36\lib\site-packages\sqlalchemy\util\langhelpers.py", line 70, in __exit__
    with_traceback=exc_tb,
  File "D:\ProgramData\Anaconda3\envs\py36\lib\site-packages\sqlalchemy\util\compat.py", line 182, in raise_
    raise exception
  File "D:\ProgramData\Anaconda3\envs\py36\lib\site-packages\sqlalchemy\pool\base.py", line 656, in __connect
    connection = pool._invoke_creator(self)
  File "D:\ProgramData\Anaconda3\envs\py36\lib\site-packages\sqlalchemy\engine\strategies.py", line 114, in connect
    return dialect.connect(*cargs, **cparams)
  File "D:\ProgramData\Anaconda3\envs\py36\lib\site-packages\sqlalchemy\engine\default.py", line 508, in connect
    return self.dbapi.connect(*cargs, **cparams)
  File "D:\ProgramData\Anaconda3\envs\py36\lib\site-packages\pymysql\connections.py", line 353, in __init__
    self.connect()
  File "D:\ProgramData\Anaconda3\envs\py36\lib\site-packages\pymysql\connections.py", line 664, in connect
    raise exc
sqlalchemy.exc.OperationalError: (pymysql.err.OperationalError) (2003, "Can't connect to MySQL server on '192.168.8.58' (timed out)")
(Background on this error at: http://sqlalche.me/e/13/e3q8)
ERROR:tornado.access:500 GET /login?username=liubin&password=123456 (127.0.0.1) 10133.56ms
ERROR:tornado.application:Uncaught exception GET /login (192.168.2.89)
HTTPServerRequest(protocol='http', host='192.168.2.89:8080', method='GET', uri='/login', version='HTTP/1.1', remote_ip='192.168.2.89')
Traceback (most recent call last):
  File "D:\ProgramData\Anaconda3\envs\py36\lib\site-packages\pymysql\connections.py", line 614, in connect
    (self.host, self.port), self.connect_timeout, **kwargs
  File "D:\ProgramData\Anaconda3\envs\py36\lib\socket.py", line 724, in create_connection
    raise err
  File "D:\ProgramData\Anaconda3\envs\py36\lib\socket.py", line 713, in create_connection
    sock.connect(sa)
socket.timeout: timed out

During handling of the above exception, another exception occurred:

Traceback (most recent call last):
  File "D:\ProgramData\Anaconda3\envs\py36\lib\site-packages\sqlalchemy\engine\base.py", line 2336, in _wrap_pool_connect
    return fn()
  File "D:\ProgramData\Anaconda3\envs\py36\lib\site-packages\sqlalchemy\pool\base.py", line 364, in connect
    return _ConnectionFairy._checkout(self)
  File "D:\ProgramData\Anaconda3\envs\py36\lib\site-packages\sqlalchemy\pool\base.py", line 778, in _checkout
    fairy = _ConnectionRecord.checkout(pool)
  File "D:\ProgramData\Anaconda3\envs\py36\lib\site-packages\sqlalchemy\pool\base.py", line 495, in checkout
    rec = pool._do_get()
  File "D:\ProgramData\Anaconda3\envs\py36\lib\site-packages\sqlalchemy\pool\impl.py", line 140, in _do_get
    self._dec_overflow()
  File "D:\ProgramData\Anaconda3\envs\py36\lib\site-packages\sqlalchemy\util\langhelpers.py", line 70, in __exit__
    with_traceback=exc_tb,
  File "D:\ProgramData\Anaconda3\envs\py36\lib\site-packages\sqlalchemy\util\compat.py", line 182, in raise_
    raise exception
  File "D:\ProgramData\Anaconda3\envs\py36\lib\site-packages\sqlalchemy\pool\impl.py", line 137, in _do_get
    return self._create_connection()
  File "D:\ProgramData\Anaconda3\envs\py36\lib\site-packages\sqlalchemy\pool\base.py", line 309, in _create_connection
    return _ConnectionRecord(self)
  File "D:\ProgramData\Anaconda3\envs\py36\lib\site-packages\sqlalchemy\pool\base.py", line 440, in __init__
    self.__connect(first_connect_check=True)
  File "D:\ProgramData\Anaconda3\envs\py36\lib\site-packages\sqlalchemy\pool\base.py", line 661, in __connect
    pool.logger.debug("Error on connect(): %s", e)
  File "D:\ProgramData\Anaconda3\envs\py36\lib\site-packages\sqlalchemy\util\langhelpers.py", line 70, in __exit__
    with_traceback=exc_tb,
  File "D:\ProgramData\Anaconda3\envs\py36\lib\site-packages\sqlalchemy\util\compat.py", line 182, in raise_
    raise exception
  File "D:\ProgramData\Anaconda3\envs\py36\lib\site-packages\sqlalchemy\pool\base.py", line 656, in __connect
    connection = pool._invoke_creator(self)
  File "D:\ProgramData\Anaconda3\envs\py36\lib\site-packages\sqlalchemy\engine\strategies.py", line 114, in connect
    return dialect.connect(*cargs, **cparams)
  File "D:\ProgramData\Anaconda3\envs\py36\lib\site-packages\sqlalchemy\engine\default.py", line 508, in connect
    return self.dbapi.connect(*cargs, **cparams)
  File "D:\ProgramData\Anaconda3\envs\py36\lib\site-packages\pymysql\connections.py", line 353, in __init__
    self.connect()
  File "D:\ProgramData\Anaconda3\envs\py36\lib\site-packages\pymysql\connections.py", line 664, in connect
    raise exc
pymysql.err.OperationalError: (2003, "Can't connect to MySQL server on '192.168.8.58' (timed out)")

The above exception was the direct cause of the following exception:

Traceback (most recent call last):
  File "D:\ProgramData\Anaconda3\envs\py36\lib\site-packages\tornado\web.py", line 1590, in _execute
    result = method(*self.path_args, **self.path_kwargs)
  File "C:\Users\Ð¡Æß\Desktop\MyTornado\handlers\public\loginhandle.py", line 21, in get
    user.open()
  File "C:\Users\Ð¡Æß\Desktop\MyTornado\handlers\public\sql_orm.py", line 38, in open
    Base.metadata.create_all(engine)
  File "D:\ProgramData\Anaconda3\envs\py36\lib\site-packages\sqlalchemy\sql\schema.py", line 4664, in create_all
    ddl.SchemaGenerator, self, checkfirst=checkfirst, tables=tables
  File "D:\ProgramData\Anaconda3\envs\py36\lib\site-packages\sqlalchemy\engine\base.py", line 2094, in _run_visitor
    with self._optional_conn_ctx_manager(connection) as conn:
  File "D:\ProgramData\Anaconda3\envs\py36\lib\contextlib.py", line 81, in __enter__
    return next(self.gen)
  File "D:\ProgramData\Anaconda3\envs\py36\lib\site-packages\sqlalchemy\engine\base.py", line 2086, in _optional_conn_ctx_manager
    with self._contextual_connect() as conn:
  File "D:\ProgramData\Anaconda3\envs\py36\lib\site-packages\sqlalchemy\engine\base.py", line 2302, in _contextual_connect
    self._wrap_pool_connect(self.pool.connect, None),
  File "D:\ProgramData\Anaconda3\envs\py36\lib\site-packages\sqlalchemy\engine\base.py", line 2340, in _wrap_pool_connect
    e, dialect, self
  File "D:\ProgramData\Anaconda3\envs\py36\lib\site-packages\sqlalchemy\engine\base.py", line 1584, in _handle_dbapi_exception_noconnection
    sqlalchemy_exception, with_traceback=exc_info[2], from_=e
  File "D:\ProgramData\Anaconda3\envs\py36\lib\site-packages\sqlalchemy\util\compat.py", line 182, in raise_
    raise exception
  File "D:\ProgramData\Anaconda3\envs\py36\lib\site-packages\sqlalchemy\engine\base.py", line 2336, in _wrap_pool_connect
    return fn()
  File "D:\ProgramData\Anaconda3\envs\py36\lib\site-packages\sqlalchemy\pool\base.py", line 364, in connect
    return _ConnectionFairy._checkout(self)
  File "D:\ProgramData\Anaconda3\envs\py36\lib\site-packages\sqlalchemy\pool\base.py", line 778, in _checkout
    fairy = _ConnectionRecord.checkout(pool)
  File "D:\ProgramData\Anaconda3\envs\py36\lib\site-packages\sqlalchemy\pool\base.py", line 495, in checkout
    rec = pool._do_get()
  File "D:\ProgramData\Anaconda3\envs\py36\lib\site-packages\sqlalchemy\pool\impl.py", line 140, in _do_get
    self._dec_overflow()
  File "D:\ProgramData\Anaconda3\envs\py36\lib\site-packages\sqlalchemy\util\langhelpers.py", line 70, in __exit__
    with_traceback=exc_tb,
  File "D:\ProgramData\Anaconda3\envs\py36\lib\site-packages\sqlalchemy\util\compat.py", line 182, in raise_
    raise exception
  File "D:\ProgramData\Anaconda3\envs\py36\lib\site-packages\sqlalchemy\pool\impl.py", line 137, in _do_get
    return self._create_connection()
  File "D:\ProgramData\Anaconda3\envs\py36\lib\site-packages\sqlalchemy\pool\base.py", line 309, in _create_connection
    return _ConnectionRecord(self)
  File "D:\ProgramData\Anaconda3\envs\py36\lib\site-packages\sqlalchemy\pool\base.py", line 440, in __init__
    self.__connect(first_connect_check=True)
  File "D:\ProgramData\Anaconda3\envs\py36\lib\site-packages\sqlalchemy\pool\base.py", line 661, in __connect
    pool.logger.debug("Error on connect(): %s", e)
  File "D:\ProgramData\Anaconda3\envs\py36\lib\site-packages\sqlalchemy\util\langhelpers.py", line 70, in __exit__
    with_traceback=exc_tb,
  File "D:\ProgramData\Anaconda3\envs\py36\lib\site-packages\sqlalchemy\util\compat.py", line 182, in raise_
    raise exception
  File "D:\ProgramData\Anaconda3\envs\py36\lib\site-packages\sqlalchemy\pool\base.py", line 656, in __connect
    connection = pool._invoke_creator(self)
  File "D:\ProgramData\Anaconda3\envs\py36\lib\site-packages\sqlalchemy\engine\strategies.py", line 114, in connect
    return dialect.connect(*cargs, **cparams)
  File "D:\ProgramData\Anaconda3\envs\py36\lib\site-packages\sqlalchemy\engine\default.py", line 508, in connect
    return self.dbapi.connect(*cargs, **cparams)
  File "D:\ProgramData\Anaconda3\envs\py36\lib\site-packages\pymysql\connections.py", line 353, in __init__
    self.connect()
  File "D:\ProgramData\Anaconda3\envs\py36\lib\site-packages\pymysql\connections.py", line 664, in connect
    raise exc
sqlalchemy.exc.OperationalError: (pymysql.err.OperationalError) (2003, "Can't connect to MySQL server on '192.168.8.58' (timed out)")
(Background on this error at: http://sqlalche.me/e/13/e3q8)
ERROR:tornado.access:500 GET /login (192.168.2.89) 10100.14ms
ERROR:tornado.application:Uncaught exception GET /login (192.168.2.89)
HTTPServerRequest(protocol='http', host='192.168.2.89:8080', method='GET', uri='/login', version='HTTP/1.1', remote_ip='192.168.2.89')
Traceback (most recent call last):
  File "D:\ProgramData\Anaconda3\envs\py36\lib\site-packages\pymysql\connections.py", line 614, in connect
    (self.host, self.port), self.connect_timeout, **kwargs
  File "D:\ProgramData\Anaconda3\envs\py36\lib\socket.py", line 724, in create_connection
    raise err
  File "D:\ProgramData\Anaconda3\envs\py36\lib\socket.py", line 713, in create_connection
    sock.connect(sa)
socket.timeout: timed out

During handling of the above exception, another exception occurred:

Traceback (most recent call last):
  File "D:\ProgramData\Anaconda3\envs\py36\lib\site-packages\sqlalchemy\engine\base.py", line 2336, in _wrap_pool_connect
    return fn()
  File "D:\ProgramData\Anaconda3\envs\py36\lib\site-packages\sqlalchemy\pool\base.py", line 364, in connect
    return _ConnectionFairy._checkout(self)
  File "D:\ProgramData\Anaconda3\envs\py36\lib\site-packages\sqlalchemy\pool\base.py", line 778, in _checkout
    fairy = _ConnectionRecord.checkout(pool)
  File "D:\ProgramData\Anaconda3\envs\py36\lib\site-packages\sqlalchemy\pool\base.py", line 495, in checkout
    rec = pool._do_get()
  File "D:\ProgramData\Anaconda3\envs\py36\lib\site-packages\sqlalchemy\pool\impl.py", line 140, in _do_get
    self._dec_overflow()
  File "D:\ProgramData\Anaconda3\envs\py36\lib\site-packages\sqlalchemy\util\langhelpers.py", line 70, in __exit__
    with_traceback=exc_tb,
  File "D:\ProgramData\Anaconda3\envs\py36\lib\site-packages\sqlalchemy\util\compat.py", line 182, in raise_
    raise exception
  File "D:\ProgramData\Anaconda3\envs\py36\lib\site-packages\sqlalchemy\pool\impl.py", line 137, in _do_get
    return self._create_connection()
  File "D:\ProgramData\Anaconda3\envs\py36\lib\site-packages\sqlalchemy\pool\base.py", line 309, in _create_connection
    return _ConnectionRecord(self)
  File "D:\ProgramData\Anaconda3\envs\py36\lib\site-packages\sqlalchemy\pool\base.py", line 440, in __init__
    self.__connect(first_connect_check=True)
  File "D:\ProgramData\Anaconda3\envs\py36\lib\site-packages\sqlalchemy\pool\base.py", line 661, in __connect
    pool.logger.debug("Error on connect(): %s", e)
  File "D:\ProgramData\Anaconda3\envs\py36\lib\site-packages\sqlalchemy\util\langhelpers.py", line 70, in __exit__
    with_traceback=exc_tb,
  File "D:\ProgramData\Anaconda3\envs\py36\lib\site-packages\sqlalchemy\util\compat.py", line 182, in raise_
    raise exception
  File "D:\ProgramData\Anaconda3\envs\py36\lib\site-packages\sqlalchemy\pool\base.py", line 656, in __connect
    connection = pool._invoke_creator(self)
  File "D:\ProgramData\Anaconda3\envs\py36\lib\site-packages\sqlalchemy\engine\strategies.py", line 114, in connect
    return dialect.connect(*cargs, **cparams)
  File "D:\ProgramData\Anaconda3\envs\py36\lib\site-packages\sqlalchemy\engine\default.py", line 508, in connect
    return self.dbapi.connect(*cargs, **cparams)
  File "D:\ProgramData\Anaconda3\envs\py36\lib\site-packages\pymysql\connections.py", line 353, in __init__
    self.connect()
  File "D:\ProgramData\Anaconda3\envs\py36\lib\site-packages\pymysql\connections.py", line 664, in connect
    raise exc
pymysql.err.OperationalError: (2003, "Can't connect to MySQL server on '192.168.8.58' (timed out)")

The above exception was the direct cause of the following exception:

Traceback (most recent call last):
  File "D:\ProgramData\Anaconda3\envs\py36\lib\site-packages\tornado\web.py", line 1590, in _execute
    result = method(*self.path_args, **self.path_kwargs)
  File "C:\Users\Ð¡Æß\Desktop\MyTornado\handlers\public\loginhandle.py", line 21, in get
    user.open()
  File "C:\Users\Ð¡Æß\Desktop\MyTornado\handlers\public\sql_orm.py", line 38, in open
    Base.metadata.create_all(engine)
  File "D:\ProgramData\Anaconda3\envs\py36\lib\site-packages\sqlalchemy\sql\schema.py", line 4664, in create_all
    ddl.SchemaGenerator, self, checkfirst=checkfirst, tables=tables
  File "D:\ProgramData\Anaconda3\envs\py36\lib\site-packages\sqlalchemy\engine\base.py", line 2094, in _run_visitor
    with self._optional_conn_ctx_manager(connection) as conn:
  File "D:\ProgramData\Anaconda3\envs\py36\lib\contextlib.py", line 81, in __enter__
    return next(self.gen)
  File "D:\ProgramData\Anaconda3\envs\py36\lib\site-packages\sqlalchemy\engine\base.py", line 2086, in _optional_conn_ctx_manager
    with self._contextual_connect() as conn:
  File "D:\ProgramData\Anaconda3\envs\py36\lib\site-packages\sqlalchemy\engine\base.py", line 2302, in _contextual_connect
    self._wrap_pool_connect(self.pool.connect, None),
  File "D:\ProgramData\Anaconda3\envs\py36\lib\site-packages\sqlalchemy\engine\base.py", line 2340, in _wrap_pool_connect
    e, dialect, self
  File "D:\ProgramData\Anaconda3\envs\py36\lib\site-packages\sqlalchemy\engine\base.py", line 1584, in _handle_dbapi_exception_noconnection
    sqlalchemy_exception, with_traceback=exc_info[2], from_=e
  File "D:\ProgramData\Anaconda3\envs\py36\lib\site-packages\sqlalchemy\util\compat.py", line 182, in raise_
    raise exception
  File "D:\ProgramData\Anaconda3\envs\py36\lib\site-packages\sqlalchemy\engine\base.py", line 2336, in _wrap_pool_connect
    return fn()
  File "D:\ProgramData\Anaconda3\envs\py36\lib\site-packages\sqlalchemy\pool\base.py", line 364, in connect
    return _ConnectionFairy._checkout(self)
  File "D:\ProgramData\Anaconda3\envs\py36\lib\site-packages\sqlalchemy\pool\base.py", line 778, in _checkout
    fairy = _ConnectionRecord.checkout(pool)
  File "D:\ProgramData\Anaconda3\envs\py36\lib\site-packages\sqlalchemy\pool\base.py", line 495, in checkout
    rec = pool._do_get()
  File "D:\ProgramData\Anaconda3\envs\py36\lib\site-packages\sqlalchemy\pool\impl.py", line 140, in _do_get
    self._dec_overflow()
  File "D:\ProgramData\Anaconda3\envs\py36\lib\site-packages\sqlalchemy\util\langhelpers.py", line 70, in __exit__
    with_traceback=exc_tb,
  File "D:\ProgramData\Anaconda3\envs\py36\lib\site-packages\sqlalchemy\util\compat.py", line 182, in raise_
    raise exception
  File "D:\ProgramData\Anaconda3\envs\py36\lib\site-packages\sqlalchemy\pool\impl.py", line 137, in _do_get
    return self._create_connection()
  File "D:\ProgramData\Anaconda3\envs\py36\lib\site-packages\sqlalchemy\pool\base.py", line 309, in _create_connection
    return _ConnectionRecord(self)
  File "D:\ProgramData\Anaconda3\envs\py36\lib\site-packages\sqlalchemy\pool\base.py", line 440, in __init__
    self.__connect(first_connect_check=True)
  File "D:\ProgramData\Anaconda3\envs\py36\lib\site-packages\sqlalchemy\pool\base.py", line 661, in __connect
    pool.logger.debug("Error on connect(): %s", e)
  File "D:\ProgramData\Anaconda3\envs\py36\lib\site-packages\sqlalchemy\util\langhelpers.py", line 70, in __exit__
    with_traceback=exc_tb,
  File "D:\ProgramData\Anaconda3\envs\py36\lib\site-packages\sqlalchemy\util\compat.py", line 182, in raise_
    raise exception
  File "D:\ProgramData\Anaconda3\envs\py36\lib\site-packages\sqlalchemy\pool\base.py", line 656, in __connect
    connection = pool._invoke_creator(self)
  File "D:\ProgramData\Anaconda3\envs\py36\lib\site-packages\sqlalchemy\engine\strategies.py", line 114, in connect
    return dialect.connect(*cargs, **cparams)
  File "D:\ProgramData\Anaconda3\envs\py36\lib\site-packages\sqlalchemy\engine\default.py", line 508, in connect
    return self.dbapi.connect(*cargs, **cparams)
  File "D:\ProgramData\Anaconda3\envs\py36\lib\site-packages\pymysql\connections.py", line 353, in __init__
    self.connect()
  File "D:\ProgramData\Anaconda3\envs\py36\lib\site-packages\pymysql\connections.py", line 664, in connect
    raise exc
sqlalchemy.exc.OperationalError: (pymysql.err.OperationalError) (2003, "Can't connect to MySQL server on '192.168.8.58' (timed out)")
(Background on this error at: http://sqlalche.me/e/13/e3q8)
ERROR:tornado.access:500 GET /login (192.168.2.89) 10017.02ms
INFO:tornado.general:C:\Users\Ð¡Æß\Desktop\MyTornado\handlers\public\loginhandle.py modified; restarting server
INFO:tornado.access:200 GET /login (192.168.2.89) 1.00ms
INFO:tornado.access:304 GET /login (192.168.2.89) 1.01ms
INFO:tornado.access:200 GET /login (192.168.2.89) 2.00ms
INFO:tornado.access:200 GET /login (192.168.2.89) 1.99ms
WARNING:tornado.access:404 GET / (::1) 17.19ms
WARNING:tornado.access:404 GET /favicon.ico (::1) 3.00ms
WARNING:tornado.access:404 GET / (::1) 3.06ms
WARNING:tornado.access:404 GET / (::1) 1.00ms
INFO:tornado.access:200 GET /login (::1) 1.01ms
INFO:tornado.access:304 GET /login (::1) 0.99ms
INFO:tornado.access:304 GET /login (::1) 1.00ms
INFO:tornado.access:304 GET /login (::1) 1.06ms
INFO:tornado.access:304 GET /login (::1) 2.01ms
INFO:tornado.access:304 GET /login (::1) 1.03ms
INFO:tornado.access:304 GET /login (::1) 0.00ms
INFO:tornado.access:304 GET /login (::1) 0.00ms
ERROR:tornado.application:Uncaught exception GET /login (::1)
HTTPServerRequest(protocol='http', host='localhost:8080', method='GET', uri='/login', version='HTTP/1.1', remote_ip='::1')
Traceback (most recent call last):
  File "D:\ProgramData\Anaconda3\envs\py36\lib\site-packages\sqlalchemy\engine\base.py", line 2336, in _wrap_pool_connect
    return fn()
  File "D:\ProgramData\Anaconda3\envs\py36\lib\site-packages\sqlalchemy\pool\base.py", line 364, in connect
    return _ConnectionFairy._checkout(self)
  File "D:\ProgramData\Anaconda3\envs\py36\lib\site-packages\sqlalchemy\pool\base.py", line 778, in _checkout
    fairy = _ConnectionRecord.checkout(pool)
  File "D:\ProgramData\Anaconda3\envs\py36\lib\site-packages\sqlalchemy\pool\base.py", line 495, in checkout
    rec = pool._do_get()
  File "D:\ProgramData\Anaconda3\envs\py36\lib\site-packages\sqlalchemy\pool\impl.py", line 140, in _do_get
    self._dec_overflow()
  File "D:\ProgramData\Anaconda3\envs\py36\lib\site-packages\sqlalchemy\util\langhelpers.py", line 70, in __exit__
    with_traceback=exc_tb,
  File "D:\ProgramData\Anaconda3\envs\py36\lib\site-packages\sqlalchemy\util\compat.py", line 182, in raise_
    raise exception
  File "D:\ProgramData\Anaconda3\envs\py36\lib\site-packages\sqlalchemy\pool\impl.py", line 137, in _do_get
    return self._create_connection()
  File "D:\ProgramData\Anaconda3\envs\py36\lib\site-packages\sqlalchemy\pool\base.py", line 309, in _create_connection
    return _ConnectionRecord(self)
  File "D:\ProgramData\Anaconda3\envs\py36\lib\site-packages\sqlalchemy\pool\base.py", line 440, in __init__
    self.__connect(first_connect_check=True)
  File "D:\ProgramData\Anaconda3\envs\py36\lib\site-packages\sqlalchemy\pool\base.py", line 661, in __connect
    pool.logger.debug("Error on connect(): %s", e)
  File "D:\ProgramData\Anaconda3\envs\py36\lib\site-packages\sqlalchemy\util\langhelpers.py", line 70, in __exit__
    with_traceback=exc_tb,
  File "D:\ProgramData\Anaconda3\envs\py36\lib\site-packages\sqlalchemy\util\compat.py", line 182, in raise_
    raise exception
  File "D:\ProgramData\Anaconda3\envs\py36\lib\site-packages\sqlalchemy\pool\base.py", line 656, in __connect
    connection = pool._invoke_creator(self)
  File "D:\ProgramData\Anaconda3\envs\py36\lib\site-packages\sqlalchemy\engine\strategies.py", line 114, in connect
    return dialect.connect(*cargs, **cparams)
  File "D:\ProgramData\Anaconda3\envs\py36\lib\site-packages\sqlalchemy\engine\default.py", line 508, in connect
    return self.dbapi.connect(*cargs, **cparams)
  File "D:\ProgramData\Anaconda3\envs\py36\lib\site-packages\pymysql\connections.py", line 353, in __init__
    self.connect()
  File "D:\ProgramData\Anaconda3\envs\py36\lib\site-packages\pymysql\connections.py", line 633, in connect
    self._request_authentication()
  File "D:\ProgramData\Anaconda3\envs\py36\lib\site-packages\pymysql\connections.py", line 907, in _request_authentication
    auth_packet = self._read_packet()
  File "D:\ProgramData\Anaconda3\envs\py36\lib\site-packages\pymysql\connections.py", line 725, in _read_packet
    packet.raise_for_error()
  File "D:\ProgramData\Anaconda3\envs\py36\lib\site-packages\pymysql\protocol.py", line 221, in raise_for_error
    err.raise_mysql_exception(self._data)
  File "D:\ProgramData\Anaconda3\envs\py36\lib\site-packages\pymysql\err.py", line 143, in raise_mysql_exception
    raise errorclass(errno, errval)
pymysql.err.OperationalError: (1045, "Access denied for user 'root'@'192.168.2.89' (using password: YES)")

The above exception was the direct cause of the following exception:

Traceback (most recent call last):
  File "D:\ProgramData\Anaconda3\envs\py36\lib\site-packages\tornado\web.py", line 1590, in _execute
    result = method(*self.path_args, **self.path_kwargs)
  File "C:\Users\Ð¡Æß\Desktop\MyTornado\handlers\public\loginhandle.py", line 22, in get
    user.open()
  File "C:\Users\Ð¡Æß\Desktop\MyTornado\handlers\public\sql_orm.py", line 38, in open
    Base.metadata.create_all(engine)
  File "D:\ProgramData\Anaconda3\envs\py36\lib\site-packages\sqlalchemy\sql\schema.py", line 4664, in create_all
    ddl.SchemaGenerator, self, checkfirst=checkfirst, tables=tables
  File "D:\ProgramData\Anaconda3\envs\py36\lib\site-packages\sqlalchemy\engine\base.py", line 2094, in _run_visitor
    with self._optional_conn_ctx_manager(connection) as conn:
  File "D:\ProgramData\Anaconda3\envs\py36\lib\contextlib.py", line 81, in __enter__
    return next(self.gen)
  File "D:\ProgramData\Anaconda3\envs\py36\lib\site-packages\sqlalchemy\engine\base.py", line 2086, in _optional_conn_ctx_manager
    with self._contextual_connect() as conn:
  File "D:\ProgramData\Anaconda3\envs\py36\lib\site-packages\sqlalchemy\engine\base.py", line 2302, in _contextual_connect
    self._wrap_pool_connect(self.pool.connect, None),
  File "D:\ProgramData\Anaconda3\envs\py36\lib\site-packages\sqlalchemy\engine\base.py", line 2340, in _wrap_pool_connect
    e, dialect, self
  File "D:\ProgramData\Anaconda3\envs\py36\lib\site-packages\sqlalchemy\engine\base.py", line 1584, in _handle_dbapi_exception_noconnection
    sqlalchemy_exception, with_traceback=exc_info[2], from_=e
  File "D:\ProgramData\Anaconda3\envs\py36\lib\site-packages\sqlalchemy\util\compat.py", line 182, in raise_
    raise exception
  File "D:\ProgramData\Anaconda3\envs\py36\lib\site-packages\sqlalchemy\engine\base.py", line 2336, in _wrap_pool_connect
    return fn()
  File "D:\ProgramData\Anaconda3\envs\py36\lib\site-packages\sqlalchemy\pool\base.py", line 364, in connect
    return _ConnectionFairy._checkout(self)
  File "D:\ProgramData\Anaconda3\envs\py36\lib\site-packages\sqlalchemy\pool\base.py", line 778, in _checkout
    fairy = _ConnectionRecord.checkout(pool)
  File "D:\ProgramData\Anaconda3\envs\py36\lib\site-packages\sqlalchemy\pool\base.py", line 495, in checkout
    rec = pool._do_get()
  File "D:\ProgramData\Anaconda3\envs\py36\lib\site-packages\sqlalchemy\pool\impl.py", line 140, in _do_get
    self._dec_overflow()
  File "D:\ProgramData\Anaconda3\envs\py36\lib\site-packages\sqlalchemy\util\langhelpers.py", line 70, in __exit__
    with_traceback=exc_tb,
  File "D:\ProgramData\Anaconda3\envs\py36\lib\site-packages\sqlalchemy\util\compat.py", line 182, in raise_
    raise exception
  File "D:\ProgramData\Anaconda3\envs\py36\lib\site-packages\sqlalchemy\pool\impl.py", line 137, in _do_get
    return self._create_connection()
  File "D:\ProgramData\Anaconda3\envs\py36\lib\site-packages\sqlalchemy\pool\base.py", line 309, in _create_connection
    return _ConnectionRecord(self)
  File "D:\ProgramData\Anaconda3\envs\py36\lib\site-packages\sqlalchemy\pool\base.py", line 440, in __init__
    self.__connect(first_connect_check=True)
  File "D:\ProgramData\Anaconda3\envs\py36\lib\site-packages\sqlalchemy\pool\base.py", line 661, in __connect
    pool.logger.debug("Error on connect(): %s", e)
  File "D:\ProgramData\Anaconda3\envs\py36\lib\site-packages\sqlalchemy\util\langhelpers.py", line 70, in __exit__
    with_traceback=exc_tb,
  File "D:\ProgramData\Anaconda3\envs\py36\lib\site-packages\sqlalchemy\util\compat.py", line 182, in raise_
    raise exception
  File "D:\ProgramData\Anaconda3\envs\py36\lib\site-packages\sqlalchemy\pool\base.py", line 656, in __connect
    connection = pool._invoke_creator(self)
  File "D:\ProgramData\Anaconda3\envs\py36\lib\site-packages\sqlalchemy\engine\strategies.py", line 114, in connect
    return dialect.connect(*cargs, **cparams)
  File "D:\ProgramData\Anaconda3\envs\py36\lib\site-packages\sqlalchemy\engine\default.py", line 508, in connect
    return self.dbapi.connect(*cargs, **cparams)
  File "D:\ProgramData\Anaconda3\envs\py36\lib\site-packages\pymysql\connections.py", line 353, in __init__
    self.connect()
  File "D:\ProgramData\Anaconda3\envs\py36\lib\site-packages\pymysql\connections.py", line 633, in connect
    self._request_authentication()
  File "D:\ProgramData\Anaconda3\envs\py36\lib\site-packages\pymysql\connections.py", line 907, in _request_authentication
    auth_packet = self._read_packet()
  File "D:\ProgramData\Anaconda3\envs\py36\lib\site-packages\pymysql\connections.py", line 725, in _read_packet
    packet.raise_for_error()
  File "D:\ProgramData\Anaconda3\envs\py36\lib\site-packages\pymysql\protocol.py", line 221, in raise_for_error
    err.raise_mysql_exception(self._data)
  File "D:\ProgramData\Anaconda3\envs\py36\lib\site-packages\pymysql\err.py", line 143, in raise_mysql_exception
    raise errorclass(errno, errval)
sqlalchemy.exc.OperationalError: (pymysql.err.OperationalError) (1045, "Access denied for user 'root'@'192.168.2.89' (using password: YES)")
(Background on this error at: http://sqlalche.me/e/13/e3q8)
ERROR:tornado.access:500 GET /login (::1) 135.86ms
ERROR:tornado.application:Uncaught exception GET /login?username=liubin&password=123456 (127.0.0.1)
HTTPServerRequest(protocol='http', host='localhost:8080', method='GET', uri='/login?username=liubin&password=123456', version='HTTP/1.1', remote_ip='127.0.0.1')
Traceback (most recent call last):
  File "D:\ProgramData\Anaconda3\envs\py36\lib\site-packages\pymysql\connections.py", line 614, in connect
    (self.host, self.port), self.connect_timeout, **kwargs
  File "D:\ProgramData\Anaconda3\envs\py36\lib\socket.py", line 724, in create_connection
    raise err
  File "D:\ProgramData\Anaconda3\envs\py36\lib\socket.py", line 713, in create_connection
    sock.connect(sa)
socket.timeout: timed out

During handling of the above exception, another exception occurred:

Traceback (most recent call last):
  File "D:\ProgramData\Anaconda3\envs\py36\lib\site-packages\sqlalchemy\engine\base.py", line 2336, in _wrap_pool_connect
    return fn()
  File "D:\ProgramData\Anaconda3\envs\py36\lib\site-packages\sqlalchemy\pool\base.py", line 364, in connect
    return _ConnectionFairy._checkout(self)
  File "D:\ProgramData\Anaconda3\envs\py36\lib\site-packages\sqlalchemy\pool\base.py", line 778, in _checkout
    fairy = _ConnectionRecord.checkout(pool)
  File "D:\ProgramData\Anaconda3\envs\py36\lib\site-packages\sqlalchemy\pool\base.py", line 495, in checkout
    rec = pool._do_get()
  File "D:\ProgramData\Anaconda3\envs\py36\lib\site-packages\sqlalchemy\pool\impl.py", line 140, in _do_get
    self._dec_overflow()
  File "D:\ProgramData\Anaconda3\envs\py36\lib\site-packages\sqlalchemy\util\langhelpers.py", line 70, in __exit__
    with_traceback=exc_tb,
  File "D:\ProgramData\Anaconda3\envs\py36\lib\site-packages\sqlalchemy\util\compat.py", line 182, in raise_
    raise exception
  File "D:\ProgramData\Anaconda3\envs\py36\lib\site-packages\sqlalchemy\pool\impl.py", line 137, in _do_get
    return self._create_connection()
  File "D:\ProgramData\Anaconda3\envs\py36\lib\site-packages\sqlalchemy\pool\base.py", line 309, in _create_connection
    return _ConnectionRecord(self)
  File "D:\ProgramData\Anaconda3\envs\py36\lib\site-packages\sqlalchemy\pool\base.py", line 440, in __init__
    self.__connect(first_connect_check=True)
  File "D:\ProgramData\Anaconda3\envs\py36\lib\site-packages\sqlalchemy\pool\base.py", line 661, in __connect
    pool.logger.debug("Error on connect(): %s", e)
  File "D:\ProgramData\Anaconda3\envs\py36\lib\site-packages\sqlalchemy\util\langhelpers.py", line 70, in __exit__
    with_traceback=exc_tb,
  File "D:\ProgramData\Anaconda3\envs\py36\lib\site-packages\sqlalchemy\util\compat.py", line 182, in raise_
    raise exception
  File "D:\ProgramData\Anaconda3\envs\py36\lib\site-packages\sqlalchemy\pool\base.py", line 656, in __connect
    connection = pool._invoke_creator(self)
  File "D:\ProgramData\Anaconda3\envs\py36\lib\site-packages\sqlalchemy\engine\strategies.py", line 114, in connect
    return dialect.connect(*cargs, **cparams)
  File "D:\ProgramData\Anaconda3\envs\py36\lib\site-packages\sqlalchemy\engine\default.py", line 508, in connect
    return self.dbapi.connect(*cargs, **cparams)
  File "D:\ProgramData\Anaconda3\envs\py36\lib\site-packages\pymysql\connections.py", line 353, in __init__
    self.connect()
  File "D:\ProgramData\Anaconda3\envs\py36\lib\site-packages\pymysql\connections.py", line 664, in connect
    raise exc
pymysql.err.OperationalError: (2003, "Can't connect to MySQL server on '192.168.2.208' (timed out)")

The above exception was the direct cause of the following exception:

Traceback (most recent call last):
  File "D:\ProgramData\Anaconda3\envs\py36\lib\site-packages\tornado\web.py", line 1590, in _execute
    result = method(*self.path_args, **self.path_kwargs)
  File "C:\Users\Ð¡Æß\Desktop\MyTornado\handlers\public\loginhandle.py", line 22, in get
    user.open()
  File "C:\Users\Ð¡Æß\Desktop\MyTornado\handlers\public\sql_orm.py", line 38, in open
    Base.metadata.create_all(engine)
  File "D:\ProgramData\Anaconda3\envs\py36\lib\site-packages\sqlalchemy\sql\schema.py", line 4664, in create_all
    ddl.SchemaGenerator, self, checkfirst=checkfirst, tables=tables
  File "D:\ProgramData\Anaconda3\envs\py36\lib\site-packages\sqlalchemy\engine\base.py", line 2094, in _run_visitor
    with self._optional_conn_ctx_manager(connection) as conn:
  File "D:\ProgramData\Anaconda3\envs\py36\lib\contextlib.py", line 81, in __enter__
    return next(self.gen)
  File "D:\ProgramData\Anaconda3\envs\py36\lib\site-packages\sqlalchemy\engine\base.py", line 2086, in _optional_conn_ctx_manager
    with self._contextual_connect() as conn:
  File "D:\ProgramData\Anaconda3\envs\py36\lib\site-packages\sqlalchemy\engine\base.py", line 2302, in _contextual_connect
    self._wrap_pool_connect(self.pool.connect, None),
  File "D:\ProgramData\Anaconda3\envs\py36\lib\site-packages\sqlalchemy\engine\base.py", line 2340, in _wrap_pool_connect
    e, dialect, self
  File "D:\ProgramData\Anaconda3\envs\py36\lib\site-packages\sqlalchemy\engine\base.py", line 1584, in _handle_dbapi_exception_noconnection
    sqlalchemy_exception, with_traceback=exc_info[2], from_=e
  File "D:\ProgramData\Anaconda3\envs\py36\lib\site-packages\sqlalchemy\util\compat.py", line 182, in raise_
    raise exception
  File "D:\ProgramData\Anaconda3\envs\py36\lib\site-packages\sqlalchemy\engine\base.py", line 2336, in _wrap_pool_connect
    return fn()
  File "D:\ProgramData\Anaconda3\envs\py36\lib\site-packages\sqlalchemy\pool\base.py", line 364, in connect
    return _ConnectionFairy._checkout(self)
  File "D:\ProgramData\Anaconda3\envs\py36\lib\site-packages\sqlalchemy\pool\base.py", line 778, in _checkout
    fairy = _ConnectionRecord.checkout(pool)
  File "D:\ProgramData\Anaconda3\envs\py36\lib\site-packages\sqlalchemy\pool\base.py", line 495, in checkout
    rec = pool._do_get()
  File "D:\ProgramData\Anaconda3\envs\py36\lib\site-packages\sqlalchemy\pool\impl.py", line 140, in _do_get
    self._dec_overflow()
  File "D:\ProgramData\Anaconda3\envs\py36\lib\site-packages\sqlalchemy\util\langhelpers.py", line 70, in __exit__
    with_traceback=exc_tb,
  File "D:\ProgramData\Anaconda3\envs\py36\lib\site-packages\sqlalchemy\util\compat.py", line 182, in raise_
    raise exception
  File "D:\ProgramData\Anaconda3\envs\py36\lib\site-packages\sqlalchemy\pool\impl.py", line 137, in _do_get
    return self._create_connection()
  File "D:\ProgramData\Anaconda3\envs\py36\lib\site-packages\sqlalchemy\pool\base.py", line 309, in _create_connection
    return _ConnectionRecord(self)
  File "D:\ProgramData\Anaconda3\envs\py36\lib\site-packages\sqlalchemy\pool\base.py", line 440, in __init__
    self.__connect(first_connect_check=True)
  File "D:\ProgramData\Anaconda3\envs\py36\lib\site-packages\sqlalchemy\pool\base.py", line 661, in __connect
    pool.logger.debug("Error on connect(): %s", e)
  File "D:\ProgramData\Anaconda3\envs\py36\lib\site-packages\sqlalchemy\util\langhelpers.py", line 70, in __exit__
    with_traceback=exc_tb,
  File "D:\ProgramData\Anaconda3\envs\py36\lib\site-packages\sqlalchemy\util\compat.py", line 182, in raise_
    raise exception
  File "D:\ProgramData\Anaconda3\envs\py36\lib\site-packages\sqlalchemy\pool\base.py", line 656, in __connect
    connection = pool._invoke_creator(self)
  File "D:\ProgramData\Anaconda3\envs\py36\lib\site-packages\sqlalchemy\engine\strategies.py", line 114, in connect
    return dialect.connect(*cargs, **cparams)
  File "D:\ProgramData\Anaconda3\envs\py36\lib\site-packages\sqlalchemy\engine\default.py", line 508, in connect
    return self.dbapi.connect(*cargs, **cparams)
  File "D:\ProgramData\Anaconda3\envs\py36\lib\site-packages\pymysql\connections.py", line 353, in __init__
    self.connect()
  File "D:\ProgramData\Anaconda3\envs\py36\lib\site-packages\pymysql\connections.py", line 664, in connect
    raise exc
sqlalchemy.exc.OperationalError: (pymysql.err.OperationalError) (2003, "Can't connect to MySQL server on '192.168.2.208' (timed out)")
(Background on this error at: http://sqlalche.me/e/13/e3q8)
ERROR:tornado.access:500 GET /login?username=liubin&password=123456 (127.0.0.1) 10211.90ms
INFO:tornado.access:200 GET /login (::1) 1.00ms
INFO:tornado.access:200 GET /login?username=liubin&password=123456 (127.0.0.1) 1.00ms
INFO:tornado.access:200 GET /login?username=liubin&password=123456 (127.0.0.1) 2.00ms
INFO:tornado.access:200 GET /login?username=liubin&password=123456 (127.0.0.1) 1.00ms
INFO:tornado.access:200 GET /login?username=liubin&password=123456 (127.0.0.1) 1.01ms
INFO:tornado.access:200 GET /login?username=liubin&password=123456 (127.0.0.1) 587.54ms
INFO:tornado.access:304 GET /login (::1) 157.03ms
INFO:tornado.access:200 GET /login?username=liubin&password=123456 (127.0.0.1) 181.01ms
INFO:tornado.access:200 GET /login (::1) 45.63ms
INFO:tornado.access:304 GET /login (::1) 43.82ms
INFO:tornado.access:304 GET /login (::1) 138.46ms
INFO:tornado.access:304 GET /login (::1) 65.71ms
INFO:tornado.access:304 GET /login (::1) 66.83ms
INFO:tornado.access:304 GET /login (::1) 42.70ms
INFO:tornado.access:304 GET /login (::1) 56.82ms
INFO:tornado.access:304 GET /login (::1) 54.18ms
INFO:tornado.access:304 GET /login (::1) 64.68ms
INFO:tornado.access:304 GET /login (::1) 51.57ms
INFO:tornado.access:304 GET /login (::1) 64.99ms
INFO:tornado.access:304 GET /login (::1) 45.15ms
INFO:tornado.access:304 GET /login (::1) 42.95ms
INFO:tornado.access:304 GET /login (::1) 54.86ms
INFO:tornado.access:304 GET /login (::1) 143.66ms
